Workbook

Sheet Ashtakavarga
A1: Ashtakavarga — Bhinnashtakavarga (BAV) and Sarvashtakavarga (SAV)
A2: Pick each contributor's sidereal sign in column B (replace the sample chart with yours). Everything below recalculates. Rahu and Ketu take no part.
A4: Contributor | B4: Sign (choose) | C4: Sign #
A5: Sun | B5: Taurus | C5: =MATCH(B5,Workings!$C$3:$N$3,0)-1 -> 1
A6: Moon | B6: Sagittarius | C6: =MATCH(B6,Workings!$C$3:$N$3,0)-1 -> 8
A7: Mars | B7: Aquarius | C7: =MATCH(B7,Workings!$C$3:$N$3,0)-1 -> 10
A8: Mercury | B8: Aries | C8: =MATCH(B8,Workings!$C$3:$N$3,0)-1 -> 0
A9: Jupiter | B9: Gemini | C9: =MATCH(B9,Workings!$C$3:$N$3,0)-1 -> 2
A10: Venus | B10: Pisces | C10: =MATCH(B10,Workings!$C$3:$N$3,0)-1 -> 11
A11: Saturn | B11: Capricorn | C11: =MATCH(B11,Workings!$C$3:$N$3,0)-1 -> 9
A12: Lagna | B12: Taurus | C12: =MATCH(B12,Workings!$C$3:$N$3,0)-1 -> 1
A14: Bhinnashtakavarga (BAV) — one row per planet
A15: Planet | B15: Aries | C15: Taurus | D15: Gemini | E15: Cancer | F15: Leo | G15: Virgo | H15: Libra | I15: Scorpio | J15: Sagittarius | K15: Capricorn | L15: Aquarius | M15: Pisces | N15: Total | O15: Classical | P15: Check
A16: Sun | B16: =Workings!C15 -> 3 | C16: =Workings!D15 -> 3 | D16: =Workings!E15 -> 2 | E16: =Workings!F15 -> 2 | F16: =Workings!G15 -> 6 | G16: =Workings!H15 -> 5 | H16: =Workings!I15 -> 5 | I16: =Workings!J15 -> 4 | ... M16: =Workings!N15 -> 4 | N16: =SUM(B16:M16) -> 48 | O16: 48 | P16: =IF(N16=O16,"OK","CHECK") -> OK
A17: Moon | B17: =Workings!C27 -> 3 | C17: =Workings!D27 -> 3 | D17: =Workings!E27 -> 6 | E17: =Workings!F27 -> 6 | F17: =Workings!G27 -> 2 | G17: =Workings!H27 -> 3 | H17: =Workings!I27 -> 4 | I17: =Workings!J27 -> 5 | ... M17: =Workings!N27 -> 5 | N17: =SUM(B17:M17) -> 49 | O17: 49 | P17: =IF(N17=O17,"OK","CHECK") -> OK
A18: Mars | B18: =Workings!C39 -> 2 | C18: =Workings!D39 -> 4 | D18: =Workings!E39 -> 1 | E18: =Workings!F39 -> 3 | F18: =Workings!G39 -> 4 | G18: =Workings!H39 -> 4 | H18: =Workings!I39 -> 5 | I18: =Workings!J39 -> 3 | ... M18: =Workings!N39 -> 4 | N18: =SUM(B18:M18) -> 39 | O18: 39 | P18: =IF(N18=O18,"OK","CHECK") -> OK
A19: Mercury | B19: =Workings!C51 -> 5 | C19: =Workings!D51 -> 5 | D19: =Workings!E51 -> 3 | E19: =Workings!F51 -> 3 | F19: =Workings!G51 -> 4 | G19: =Workings!H51 -> 5 | H19: =Workings!I51 -> 6 | I19: =Workings!J51 -> 4 | ... M19: =Workings!N51 -> 6 | N19: =SUM(B19:M19) -> 54 | O19: 54 | P19: =IF(N19=O19,"OK","CHECK") -> OK
A20: Jupiter | B20: =Workings!C63 -> 4 | C20: =Workings!D63 -> 5 | D20: =Workings!E63 -> 5 | E20: =Workings!F63 -> 4 | F20: =Workings!G63 -> 7 | G20: =Workings!H63 -> 4 | H20: =Workings!I63 -> 2 | I20: =Workings!J63 -> 4 | ... M20: =Workings!N63 -> 5 | N20: =SUM(B20:M20) -> 56 | O20: 56 | P20: =IF(N20=O20,"OK","CHECK") -> OK
A21: Venus | B21: =Workings!C75 -> 6 | C21: =Workings!D75 -> 4 | D21: =Workings!E75 -> 3 | E21: =Workings!F75 -> 4 | F21: =Workings!G75 -> 4 | G21: =Workings!H75 -> 3 | H21: =Workings!I75 -> 5 | I21: =Workings!J75 -> 3 | ... M21: =Workings!N75 -> 6 | N21: =SUM(B21:M21) -> 52 | O21: 52 | P21: =IF(N21=O21,"OK","CHECK") -> OK
A22: Saturn | B22: =Workings!C87 -> 2 | C22: =Workings!D87 -> 5 | D22: =Workings!E87 -> 3 | E22: =Workings!F87 -> 2 | F22: =Workings!G87 -> 3 | G22: =Workings!H87 -> 1 | H22: =Workings!I87 -> 3 | I22: =Workings!J87 -> 5 | ... M22: =Workings!N87 -> 4 | N22: =SUM(B22:M22) -> 39 | O22: 39 | P22: =IF(N22=O22,"OK","CHECK") -> OK
A24: Sarvashtakavarga (SAV) — all seven planets together
A25: Sign | B25: Aries | C25: Taurus | D25: Gemini | E25: Cancer | F25: Leo | G25: Virgo | H25: Libra | I25: Scorpio | J25: Sagittarius | K25: Capricorn | L25: Aquarius | M25: Pisces | N25: Total | O25: Classical | P25: Check
A26: House from Lagna | B26: =MOD(Workings!C$4-$C$12,12)+1 -> 12 | C26: =MOD(Workings!D$4-$C$12,12)+1 -> 1 | D26: =MOD(Workings!E$4-$C$12,12)+1 -> 2 | E26: =MOD(Workings!F$4-$C$12,12)+1 -> 3 | F26: =MOD(Workings!G$4-$C$12,12)+1 -> 4 | G26: =MOD(Workings!H$4-$C$12,12)+1 -> 5 | H26: =MOD(Workings!I$4-$C$12,12)+1 -> 6 | I26: =MOD(Workings!J$4-$C$12,12)+1 -> 7 | ... M26: =MOD(Workings!N$4-$C$12,12)+1 -> 11
A27: SAV bindus | B27: =SUM(B16:B22) -> 25 | C27: =SUM(C16:C22) -> 29 | D27: =SUM(D16:D22) -> 23 | E27: =SUM(E16:E22) -> 24 | F27: =SUM(F16:F22) -> 30 | G27: =SUM(G16:G22) -> 25 | H27: =SUM(H16:H22) -> 30 | I27: =SUM(I16:I22) -> 28 | ... M27: =SUM(M16:M22) -> 34 | N27: =SUM(B27:M27) -> 337 | O27: 337 | P27: =IF(AND(N27=O27,COUNTIF(P16:P22,"OK")=7),"OK","CHECK") -> OK
A29: Shading — BAV: 5 or more bindus strong (green), 3-4 average (amber), fewer than 3 weak (red).
A30: Shading — SAV: 30 or more strong, 25-29 average, fewer than 25 weak. The SAV always totals 337 (about 28 per sign).
A31: Bold cell in the BAV table = that planet's own natal sign. Orange header = the Lagna sign.
A32: These are the unreduced (pre-sodhana) figures: no Trikona or Ekadhipatya reduction is applied.

Sheet Rules
A1: Ashtakavarga rules — houses (counted from the contributor, 1 = its own sign) that give a bindu
A2: 1 = the contributor gives one bindu to the target planet's chart in that house from itself. Tables follow Brihat Parashara Hora Shastra, ch. 66. Edit a flag to test another school; the check cells at right turn to CHECK if a planet's total leaves its classical value.
A3: Moon rows: the BPHS text is used (Moon<-Moon has house 9, Moon<-Mars lacks 9, Moon<-Jupiter has 2 not 12). Most modern books differ: Moon<-Moon remove 9; Moon<-Mars add 9; Moon<-Jupiter replace 2 with 12.
A4: Target planet | B4: Contributor | C4: House 1 | D4: House 2 | E4: House 3 | F4: House 4 | G4: House 5 | H4: House 6 | I4: House 7 | J4: House 8 | K4: House 9 | L4: House 10 | M4: House 11 | N4: House 12 | O4: Bindus | Q4: Target | R4: Classical | S4: In table | T4: Check
A5: Sun | B5: Sun | C5: 1 | D5: 1 | E5: 0 | F5: 1 | G5: 0 | H5: 0 | I5: 1 | J5: 1 | K5: 1 | L5: 1 | M5: 1 | N5: 0 | O5: =SUM(C5:N5) -> 8 | Q5: Sun | R5: 48 | S5: =SUMIF($A$5:$A$60,Q5,$O$5:$O$60) -> 48 | T5: =IF(S5=R5,"OK","CHECK") -> OK
A6: Sun | B6: Moon | C6: 0 | D6: 0 | E6: 1 | F6: 0 | G6: 0 | H6: 1 | I6: 0 | J6: 0 | K6: 0 | L6: 1 | M6: 1 | N6: 0 | O6: =SUM(C6:N6) -> 4 | Q6: Moon | R6: 49 | S6: =SUMIF($A$5:$A$60,Q6,$O$5:$O$60) -> 49 | T6: =IF(S6=R6,"OK","CHECK") -> OK
A7: Sun | B7: Mars | C7: 1 | D7: 1 | E7: 0 | F7: 1 | G7: 0 | H7: 0 | I7: 1 | J7: 1 | K7: 1 | L7: 1 | M7: 1 | N7: 0 | O7: =SUM(C7:N7) -> 8 | Q7: Mars | R7: 39 | S7: =SUMIF($A$5:$A$60,Q7,$O$5:$O$60) -> 39 | T7: =IF(S7=R7,"OK","CHECK") -> OK
A8: Sun | B8: Mercury | C8: 0 | D8: 0 | E8: 1 | F8: 0 | G8: 1 | H8: 1 | I8: 0 | J8: 0 | K8: 1 | L8: 1 | M8: 1 | N8: 1 | O8: =SUM(C8:N8) -> 7 | Q8: Mercury | R8: 54 | S8: =SUMIF($A$5:$A$60,Q8,$O$5:$O$60) -> 54 | T8: =IF(S8=R8,"OK","CHECK") -> OK
A9: Sun | B9: Jupiter | C9: 0 | D9: 0 | E9: 0 | F9: 0 | G9: 1 | H9: 1 | I9: 0 | J9: 0 | K9: 1 | L9: 0 | M9: 1 | N9: 0 | O9: =SUM(C9:N9) -> 4 | Q9: Jupiter | R9: 56 | S9: =SUMIF($A$5:$A$60,Q9,$O$5:$O$60) -> 56 | T9: =IF(S9=R9,"OK","CHECK") -> OK
A10: Sun | B10: Venus | C10: 0 | D10: 0 | E10: 0 | F10: 0 | G10: 0 | H10: 1 | I10: 1 | J10: 0 | K10: 0 | L10: 0 | M10: 0 | N10: 1 | O10: =SUM(C10:N10) -> 3 | Q10: Venus | R10: 52 | S10: =SUMIF($A$5:$A$60,Q10,$O$5:$O$60) -> 52 | T10: =IF(S10=R10,"OK","CHECK") -> OK
A11: Sun | B11: Saturn | C11: 1 | D11: 1 | E11: 0 | F11: 1 | G11: 0 | H11: 0 | I11: 1 | J11: 1 | K11: 1 | L11: 1 | M11: 1 | N11: 0 | O11: =SUM(C11:N11) -> 8 | Q11: Saturn | R11: 39 | S11: =SUMIF($A$5:$A$60,Q11,$O$5:$O$60) -> 39 | T11: =IF(S11=R11,"OK","CHECK") -> OK
A12: Sun | B12: Lagna | C12: 0 | D12: 0 | E12: 1 | F12: 1 | G12: 0 | H12: 1 | I12: 0 | J12: 0 | K12: 0 | L12: 1 | M12: 1 | N12: 1 | O12: =SUM(C12:N12) -> 6 | Q12: All | R12: =SUM(R5:R11) -> 337 | S12: =SUM(S5:S11) -> 337 | T12: =IF(S12=R12,"OK","CHECK") -> OK
A13: Moon | B13: Sun | C13: 0 | D13: 0 | E13: 1 | F13: 0 | G13: 0 | H13: 1 | I13: 1 | J13: 1 | K13: 0 | L13: 1 | M13: 1 | N13: 0 | O13: =SUM(C13:N13) -> 6
A14: Moon | B14: Moon | C14: 1 | D14: 0 | E14: 1 | F14: 0 | G14: 0 | H14: 1 | I14: 1 | J14: 0 | K14: 1 | L14: 1 | M14: 1 | N14: 0 | O14: =SUM(C14:N14) -> 7
A15: Moon | B15: Mars | C15: 0 | D15: 1 | E15: 1 | F15: 0 | G15: 1 | H15: 1 | I15: 0 | J15: 0 | K15: 0 | L15: 1 | M15: 1 | N15: 0 | O15: =SUM(C15:N15) -> 6
A16: Moon | B16: Mercury | C16: 1 | D16: 0 | E16: 1 | F16: 1 | G16: 1 | H16: 0 | I16: 1 | J16: 1 | K16: 0 | L16: 1 | M16: 1 | N16: 0 | O16: =SUM(C16:N16) -> 8
A17: Moon | B17: Jupiter | C17: 1 | D17: 1 | E17: 0 | F17: 1 | G17: 0 | H17: 0 | I17: 1 | J17: 1 | K17: 0 | L17: 1 | M17: 1 | N17: 0 | O17: =SUM(C17:N17) -> 7
A18: Moon | B18: Venus | C18: 0 | D18: 0 | E18: 1 | F18: 1 | G18: 1 | H18: 0 | I18: 1 | J18: 0 | K18: 1 | L18: 1 | M18: 1 | N18: 0 | O18: =SUM(C18:N18) -> 7
A19: Moon | B19: Saturn | C19: 0 | D19: 0 | E19: 1 | F19: 0 | G19: 1 | H19: 1 | I19: 0 | J19: 0 | K19: 0 | L19: 0 | M19: 1 | N19: 0 | O19: =SUM(C19:N19) -> 4
A20: Moon | B20: Lagna | C20: 0 | D20: 0 | E20: 1 | F20: 0 | G20: 0 | H20: 1 | I20: 0 | J20: 0 | K20: 0 | L20: 1 | M20: 1 | N20: 0 | O20: =SUM(C20:N20) -> 4
A21: Mars | B21: Sun | C21: 0 | D21: 0 | E21: 1 | F21: 0 | G21: 1 | H21: 1 | I21: 0 | J21: 0 | K21: 0 | L21: 1 | M21: 1 | N21: 0 | O21: =SUM(C21:N21) -> 5
A22: Mars | B22: Moon | C22: 0 | D22: 0 | E22: 1 | F22: 0 | G22: 0 | H22: 1 | I22: 0 | J22: 0 | K22: 0 | L22: 0 | M22: 1 | N22: 0 | O22: =SUM(C22:N22) -> 3
A23: Mars | B23: Mars | C23: 1 | D23: 1 | E23: 0 | F23: 1 | G23: 0 | H23: 0 | I23: 1 | J23: 1 | K23: 0 | L23: 1 | M23: 1 | N23: 0 | O23: =SUM(C23:N23) -> 7
A24: Mars | B24: Mercury | C24: 0 | D24: 0 | E24: 1 | F24: 0 | G24: 1 | H24: 1 | I24: 0 | J24: 0 | K24: 0 | L24: 0 | M24: 1 | N24: 0 | O24: =SUM(C24:N24) -> 4
... A60: Saturn | B60: Lagna | C60: 1 | D60: 0 | E60: 1 | F60: 1 | G60: 0 | H60: 1 | I60: 0 | J60: 0 | K60: 0 | L60: 1 | M60: 1 | N60: 0 | O60: =SUM(C60:N60) -> 6

Sheet Workings
A1: Workings — what each contributor gives each sign, planet by planet
A3: Sign | C3: Aries | D3: Taurus | E3: Gemini | F3: Cancer | G3: Leo | H3: Virgo | I3: Libra | J3: Scorpio | K3: Sagittarius | L3: Capricorn | M3: Aquarius | N3: Pisces
A4: Sign # (0 = Aries) | C4: 0 | D4: 1 | E4: 2 | F4: 3 | G4: 4 | H4: 5 | I4: 6 | J4: 7 | K4: 8 | L4: 9 | M4: 10 | N4: 11
A6: Sun Ashtakavarga (classical total 48) | B6: From sign # | O6: Bindus given
A7: Sun | B7: =Ashtakavarga!$C$5 -> 1 | C7: =INDEX(Rules!$C$5:$N$5,MOD(C$4-$B7,12)+1) -> 0 | D7: =INDEX(Rules!$C$5:$N$5,MOD(D$4-$B7,12)+1) -> 1 | E7: =INDEX(Rules!$C$5:$N$5,MOD(E$4-$B7,12)+1) -> 1 | F7: =INDEX(Rules!$C$5:$N$5,MOD(F$4-$B7,12)+1) -> 0 | G7: =INDEX(Rules!$C$5:$N$5,MOD(G$4-$B7,12)+1) -> 1 | H7: =INDEX(Rules!$C$5:$N$5,MOD(H$4-$B7,12)+1) -> 0 | I7: =INDEX(Rules!$C$5:$N$5,MOD(I$4-$B7,12)+1) -> 0 | J7: =INDEX(Rules!$C$5:$N$5,MOD(J$4-$B7,12)+1) -> 1 | ... N7: =INDEX(Rules!$C$5:$N$5,MOD(N$4-$B7,12)+1) -> 1 | O7: =SUM(C7:N7) -> 8
A8: Moon | B8: =Ashtakavarga!$C$6 -> 8 | C8: =INDEX(Rules!$C$6:$N$6,MOD(C$4-$B8,12)+1) -> 0 | D8: =INDEX(Rules!$C$6:$N$6,MOD(D$4-$B8,12)+1) -> 1 | E8: =INDEX(Rules!$C$6:$N$6,MOD(E$4-$B8,12)+1) -> 0 | F8: =INDEX(Rules!$C$6:$N$6,MOD(F$4-$B8,12)+1) -> 0 | G8: =INDEX(Rules!$C$6:$N$6,MOD(G$4-$B8,12)+1) -> 0 | H8: =INDEX(Rules!$C$6:$N$6,MOD(H$4-$B8,12)+1) -> 1 | I8: =INDEX(Rules!$C$6:$N$6,MOD(I$4-$B8,12)+1) -> 1 | J8: =INDEX(Rules!$C$6:$N$6,MOD(J$4-$B8,12)+1) -> 0 | ... N8: =INDEX(Rules!$C$6:$N$6,MOD(N$4-$B8,12)+1) -> 0 | O8: =SUM(C8:N8) -> 4
A9: Mars | B9: =Ashtakavarga!$C$7 -> 10 | C9: =INDEX(Rules!$C$7:$N$7,MOD(C$4-$B9,12)+1) -> 0 | D9: =INDEX(Rules!$C$7:$N$7,MOD(D$4-$B9,12)+1) -> 1 | E9: =INDEX(Rules!$C$7:$N$7,MOD(E$4-$B9,12)+1) -> 0 | F9: =INDEX(Rules!$C$7:$N$7,MOD(F$4-$B9,12)+1) -> 0 | G9: =INDEX(Rules!$C$7:$N$7,MOD(G$4-$B9,12)+1) -> 1 | H9: =INDEX(Rules!$C$7:$N$7,MOD(H$4-$B9,12)+1) -> 1 | I9: =INDEX(Rules!$C$7:$N$7,MOD(I$4-$B9,12)+1) -> 1 | J9: =INDEX(Rules!$C$7:$N$7,MOD(J$4-$B9,12)+1) -> 1 | ... N9: =INDEX(Rules!$C$7:$N$7,MOD(N$4-$B9,12)+1) -> 1 | O9: =SUM(C9:N9) -> 8
A10: Mercury | B10: =Ashtakavarga!$C$8 -> 0 | C10: =INDEX(Rules!$C$8:$N$8,MOD(C$4-$B10,12)+1) -> 0 | D10: =INDEX(Rules!$C$8:$N$8,MOD(D$4-$B10,12)+1) -> 0 | E10: =INDEX(Rules!$C$8:$N$8,MOD(E$4-$B10,12)+1) -> 1 | F10: =INDEX(Rules!$C$8:$N$8,MOD(F$4-$B10,12)+1) -> 0 | G10: =INDEX(Rules!$C$8:$N$8,MOD(G$4-$B10,12)+1) -> 1 | H10: =INDEX(Rules!$C$8:$N$8,MOD(H$4-$B10,12)+1) -> 1 | I10: =INDEX(Rules!$C$8:$N$8,MOD(I$4-$B10,12)+1) -> 0 | J10: =INDEX(Rules!$C$8:$N$8,MOD(J$4-$B10,12)+1) -> 0 | ... N10: =INDEX(Rules!$C$8:$N$8,MOD(N$4-$B10,12)+1) -> 1 | O10: =SUM(C10:N10) -> 7
A11: Jupiter | B11: =Ashtakavarga!$C$9 -> 2 | C11: =INDEX(Rules!$C$9:$N$9,MOD(C$4-$B11,12)+1) -> 1 | D11: =INDEX(Rules!$C$9:$N$9,MOD(D$4-$B11,12)+1) -> 0 | E11: =INDEX(Rules!$C$9:$N$9,MOD(E$4-$B11,12)+1) -> 0 | F11: =INDEX(Rules!$C$9:$N$9,MOD(F$4-$B11,12)+1) -> 0 | G11: =INDEX(Rules!$C$9:$N$9,MOD(G$4-$B11,12)+1) -> 0 | H11: =INDEX(Rules!$C$9:$N$9,MOD(H$4-$B11,12)+1) -> 0 | I11: =INDEX(Rules!$C$9:$N$9,MOD(I$4-$B11,12)+1) -> 1 | J11: =INDEX(Rules!$C$9:$N$9,MOD(J$4-$B11,12)+1) -> 1 | ... N11: =INDEX(Rules!$C$9:$N$9,MOD(N$4-$B11,12)+1) -> 0 | O11: =SUM(C11:N11) -> 4
A12: Venus | B12: =Ashtakavarga!$C$10 -> 11 | C12: =INDEX(Rules!$C$10:$N$10,MOD(C$4-$B12,12)+1) -> 0 | D12: =INDEX(Rules!$C$10:$N$10,MOD(D$4-$B12,12)+1) -> 0 | E12: =INDEX(Rules!$C$10:$N$10,MOD(E$4-$B12,12)+1) -> 0 | F12: =INDEX(Rules!$C$10:$N$10,MOD(F$4-$B12,12)+1) -> 0 | G12: =INDEX(Rules!$C$10:$N$10,MOD(G$4-$B12,12)+1) -> 1 | H12: =INDEX(Rules!$C$10:$N$10,MOD(H$4-$B12,12)+1) -> 1 | I12: =INDEX(Rules!$C$10:$N$10,MOD(I$4-$B12,12)+1) -> 0 | J12: =INDEX(Rules!$C$10:$N$10,MOD(J$4-$B12,12)+1) -> 0 | ... N12: =INDEX(Rules!$C$10:$N$10,MOD(N$4-$B12,12)+1) -> 0 | O12: =SUM(C12:N12) -> 3
A13: Saturn | B13: =Ashtakavarga!$C$11 -> 9 | C13: =INDEX(Rules!$C$11:$N$11,MOD(C$4-$B13,12)+1) -> 1 | D13: =INDEX(Rules!$C$11:$N$11,MOD(D$4-$B13,12)+1) -> 0 | E13: =INDEX(Rules!$C$11:$N$11,MOD(E$4-$B13,12)+1) -> 0 | F13: =INDEX(Rules!$C$11:$N$11,MOD(F$4-$B13,12)+1) -> 1 | G13: =INDEX(Rules!$C$11:$N$11,MOD(G$4-$B13,12)+1) -> 1 | H13: =INDEX(Rules!$C$11:$N$11,MOD(H$4-$B13,12)+1) -> 1 | I13: =INDEX(Rules!$C$11:$N$11,MOD(I$4-$B13,12)+1) -> 1 | J13: =INDEX(Rules!$C$11:$N$11,MOD(J$4-$B13,12)+1) -> 1 | ... N13: =INDEX(Rules!$C$11:$N$11,MOD(N$4-$B13,12)+1) -> 0 | O13: =SUM(C13:N13) -> 8
A14: Lagna | B14: =Ashtakavarga!$C$12 -> 1 | C14: =INDEX(Rules!$C$12:$N$12,MOD(C$4-$B14,12)+1) -> 1 | D14: =INDEX(Rules!$C$12:$N$12,MOD(D$4-$B14,12)+1) -> 0 | E14: =INDEX(Rules!$C$12:$N$12,MOD(E$4-$B14,12)+1) -> 0 | F14: =INDEX(Rules!$C$12:$N$12,MOD(F$4-$B14,12)+1) -> 1 | G14: =INDEX(Rules!$C$12:$N$12,MOD(G$4-$B14,12)+1) -> 1 | H14: =INDEX(Rules!$C$12:$N$12,MOD(H$4-$B14,12)+1) -> 0 | I14: =INDEX(Rules!$C$12:$N$12,MOD(I$4-$B14,12)+1) -> 1 | J14: =INDEX(Rules!$C$12:$N$12,MOD(J$4-$B14,12)+1) -> 0 | ... N14: =INDEX(Rules!$C$12:$N$12,MOD(N$4-$B14,12)+1) -> 1 | O14: =SUM(C14:N14) -> 6
A15: Sun BAV | C15: =SUM(C7:C14) -> 3 | D15: =SUM(D7:D14) -> 3 | E15: =SUM(E7:E14) -> 2 | F15: =SUM(F7:F14) -> 2 | G15: =SUM(G7:G14) -> 6 | H15: =SUM(H7:H14) -> 5 | I15: =SUM(I7:I14) -> 5 | J15: =SUM(J7:J14) -> 4 | ... N15: =SUM(N7:N14) -> 4 | O15: =SUM(C15:N15) -> 48
A18: Moon Ashtakavarga (classical total 49) | B18: From sign # | O18: Bindus given
A19: Sun | B19: =Ashtakavarga!$C$5 -> 1 | C19: =INDEX(Rules!$C$13:$N$13,MOD(C$4-$B19,12)+1) -> 0 | D19: =INDEX(Rules!$C$13:$N$13,MOD(D$4-$B19,12)+1) -> 0 | E19: =INDEX(Rules!$C$13:$N$13,MOD(E$4-$B19,12)+1) -> 0 | F19: =INDEX(Rules!$C$13:$N$13,MOD(F$4-$B19,12)+1) -> 1 | G19: =INDEX(Rules!$C$13:$N$13,MOD(G$4-$B19,12)+1) -> 0 | H19: =INDEX(Rules!$C$13:$N$13,MOD(H$4-$B19,12)+1) -> 0 | I19: =INDEX(Rules!$C$13:$N$13,MOD(I$4-$B19,12)+1) -> 1 | J19: =INDEX(Rules!$C$13:$N$13,MOD(J$4-$B19,12)+1) -> 1 | ... N19: =INDEX(Rules!$C$13:$N$13,MOD(N$4-$B19,12)+1) -> 1 | O19: =SUM(C19:N19) -> 6
A20: Moon | B20: =Ashtakavarga!$C$6 -> 8 | C20: =INDEX(Rules!$C$14:$N$14,MOD(C$4-$B20,12)+1) -> 0 | D20: =INDEX(Rules!$C$14:$N$14,MOD(D$4-$B20,12)+1) -> 1 | E20: =INDEX(Rules!$C$14:$N$14,MOD(E$4-$B20,12)+1) -> 1 | F20: =INDEX(Rules!$C$14:$N$14,MOD(F$4-$B20,12)+1) -> 0 | G20: =INDEX(Rules!$C$14:$N$14,MOD(G$4-$B20,12)+1) -> 1 | H20: =INDEX(Rules!$C$14:$N$14,MOD(H$4-$B20,12)+1) -> 1 | I20: =INDEX(Rules!$C$14:$N$14,MOD(I$4-$B20,12)+1) -> 1 | J20: =INDEX(Rules!$C$14:$N$14,MOD(J$4-$B20,12)+1) -> 0 | ... N20: =INDEX(Rules!$C$14:$N$14,MOD(N$4-$B20,12)+1) -> 0 | O20: =SUM(C20:N20) -> 7
A21: Mars | B21: =Ashtakavarga!$C$7 -> 10 | C21: =INDEX(Rules!$C$15:$N$15,MOD(C$4-$B21,12)+1) -> 1 | D21: =INDEX(Rules!$C$15:$N$15,MOD(D$4-$B21,12)+1) -> 0 | E21: =INDEX(Rules!$C$15:$N$15,MOD(E$4-$B21,12)+1) -> 1 | F21: =INDEX(Rules!$C$15:$N$15,MOD(F$4-$B21,12)+1) -> 1 | G21: =INDEX(Rules!$C$15:$N$15,MOD(G$4-$B21,12)+1) -> 0 | H21: =INDEX(Rules!$C$15:$N$15,MOD(H$4-$B21,12)+1) -> 0 | I21: =INDEX(Rules!$C$15:$N$15,MOD(I$4-$B21,12)+1) -> 0 | J21: =INDEX(Rules!$C$15:$N$15,MOD(J$4-$B21,12)+1) -> 1 | ... N21: =INDEX(Rules!$C$15:$N$15,MOD(N$4-$B21,12)+1) -> 1 | O21: =SUM(C21:N21) -> 6
A22: Mercury | B22: =Ashtakavarga!$C$8 -> 0 | C22: =INDEX(Rules!$C$16:$N$16,MOD(C$4-$B22,12)+1) -> 1 | D22: =INDEX(Rules!$C$16:$N$16,MOD(D$4-$B22,12)+1) -> 0 | E22: =INDEX(Rules!$C$16:$N$16,MOD(E$4-$B22,12)+1) -> 1 | F22: =INDEX(Rules!$C$16:$N$16,MOD(F$4-$B22,12)+1) -> 1 | G22: =INDEX(Rules!$C$16:$N$16,MOD(G$4-$B22,12)+1) -> 1 | H22: =INDEX(Rules!$C$16:$N$16,MOD(H$4-$B22,12)+1) -> 0 | I22: =INDEX(Rules!$C$16:$N$16,MOD(I$4-$B22,12)+1) -> 1 | J22: =INDEX(Rules!$C$16:$N$16,MOD(J$4-$B22,12)+1) -> 1 | ... N22: =INDEX(Rules!$C$16:$N$16,MOD(N$4-$B22,12)+1) -> 0 | O22: =SUM(C22:N22) -> 8
A23: Jupiter | B23: =Ashtakavarga!$C$9 -> 2 | C23: =INDEX(Rules!$C$17:$N$17,MOD(C$4-$B23,12)+1) -> 1 | D23: =INDEX(Rules!$C$17:$N$17,MOD(D$4-$B23,12)+1) -> 0 | E23: =INDEX(Rules!$C$17:$N$17,MOD(E$4-$B23,12)+1) -> 1 | F23: =INDEX(Rules!$C$17:$N$17,MOD(F$4-$B23,12)+1) -> 1 | G23: =INDEX(Rules!$C$17:$N$17,MOD(G$4-$B23,12)+1) -> 0 | H23: =INDEX(Rules!$C$17:$N$17,MOD(H$4-$B23,12)+1) -> 1 | I23: =INDEX(Rules!$C$17:$N$17,MOD(I$4-$B23,12)+1) -> 0 | J23: =INDEX(Rules!$C$17:$N$17,MOD(J$4-$B23,12)+1) -> 0 | ... N23: =INDEX(Rules!$C$17:$N$17,MOD(N$4-$B23,12)+1) -> 1 | O23: =SUM(C23:N23) -> 7
A24: Venus | B24: =Ashtakavarga!$C$10 -> 11 | C24: =INDEX(Rules!$C$18:$N$18,MOD(C$4-$B24,12)+1) -> 0 | D24: =INDEX(Rules!$C$18:$N$18,MOD(D$4-$B24,12)+1) -> 1 | E24: =INDEX(Rules!$C$18:$N$18,MOD(E$4-$B24,12)+1) -> 1 | F24: =INDEX(Rules!$C$18:$N$18,MOD(F$4-$B24,12)+1) -> 1 | G24: =INDEX(Rules!$C$18:$N$18,MOD(G$4-$B24,12)+1) -> 0 | H24: =INDEX(Rules!$C$18:$N$18,MOD(H$4-$B24,12)+1) -> 1 | I24: =INDEX(Rules!$C$18:$N$18,MOD(I$4-$B24,12)+1) -> 0 | J24: =INDEX(Rules!$C$18:$N$18,MOD(J$4-$B24,12)+1) -> 1 | ... N24: =INDEX(Rules!$C$18:$N$18,MOD(N$4-$B24,12)+1) -> 0 | O24: =SUM(C24:N24) -> 7
A25: Saturn | B25: =Ashtakavarga!$C$11 -> 9 | C25: =INDEX(Rules!$C$19:$N$19,MOD(C$4-$B25,12)+1) -> 0 | D25: =INDEX(Rules!$C$19:$N$19,MOD(D$4-$B25,12)+1) -> 1 | E25: =INDEX(Rules!$C$19:$N$19,MOD(E$4-$B25,12)+1) -> 1 | F25: =INDEX(Rules!$C$19:$N$19,MOD(F$4-$B25,12)+1) -> 0 | G25: =INDEX(Rules!$C$19:$N$19,MOD(G$4-$B25,12)+1) -> 0 | H25: =INDEX(Rules!$C$19:$N$19,MOD(H$4-$B25,12)+1) -> 0 | I25: =INDEX(Rules!$C$19:$N$19,MOD(I$4-$B25,12)+1) -> 0 | J25: =INDEX(Rules!$C$19:$N$19,MOD(J$4-$B25,12)+1) -> 1 | ... N25: =INDEX(Rules!$C$19:$N$19,MOD(N$4-$B25,12)+1) -> 1 | O25: =SUM(C25:N25) -> 4
A26: Lagna | B26: =Ashtakavarga!$C$12 -> 1 | C26: =INDEX(Rules!$C$20:$N$20,MOD(C$4-$B26,12)+1) -> 0 | D26: =INDEX(Rules!$C$20:$N$20,MOD(D$4-$B26,12)+1) -> 0 | E26: =INDEX(Rules!$C$20:$N$20,MOD(E$4-$B26,12)+1) -> 0 | F26: =INDEX(Rules!$C$20:$N$20,MOD(F$4-$B26,12)+1) -> 1 | G26: =INDEX(Rules!$C$20:$N$20,MOD(G$4-$B26,12)+1) -> 0 | H26: =INDEX(Rules!$C$20:$N$20,MOD(H$4-$B26,12)+1) -> 0 | I26: =INDEX(Rules!$C$20:$N$20,MOD(I$4-$B26,12)+1) -> 1 | J26: =INDEX(Rules!$C$20:$N$20,MOD(J$4-$B26,12)+1) -> 0 | ... N26: =INDEX(Rules!$C$20:$N$20,MOD(N$4-$B26,12)+1) -> 1 | O26: =SUM(C26:N26) -> 4
A27: Moon BAV | C27: =SUM(C19:C26) -> 3 | D27: =SUM(D19:D26) -> 3 | E27: =SUM(E19:E26) -> 6 | F27: =SUM(F19:F26) -> 6 | G27: =SUM(G19:G26) -> 2 | H27: =SUM(H19:H26) -> 3 | I27: =SUM(I19:I26) -> 4 | J27: =SUM(J19:J26) -> 5 | ... N27: =SUM(N19:N26) -> 5 | O27: =SUM(C27:N27) -> 49
A30: Mars Ashtakavarga (classical total 39) | B30: From sign # | O30: Bindus given
A31: Sun | B31: =Ashtakavarga!$C$5 -> 1 | C31: =INDEX(Rules!$C$21:$N$21,MOD(C$4-$B31,12)+1) -> 0 | D31: =INDEX(Rules!$C$21:$N$21,MOD(D$4-$B31,12)+1) -> 0 | E31: =INDEX(Rules!$C$21:$N$21,MOD(E$4-$B31,12)+1) -> 0 | F31: =INDEX(Rules!$C$21:$N$21,MOD(F$4-$B31,12)+1) -> 1 | G31: =INDEX(Rules!$C$21:$N$21,MOD(G$4-$B31,12)+1) -> 0 | H31: =INDEX(Rules!$C$21:$N$21,MOD(H$4-$B31,12)+1) -> 1 | I31: =INDEX(Rules!$C$21:$N$21,MOD(I$4-$B31,12)+1) -> 1 | J31: =INDEX(Rules!$C$21:$N$21,MOD(J$4-$B31,12)+1) -> 0 | ... N31: =INDEX(Rules!$C$21:$N$21,MOD(N$4-$B31,12)+1) -> 1 | O31: =SUM(C31:N31) -> 5
A32: Moon | B32: =Ashtakavarga!$C$6 -> 8 | C32: =INDEX(Rules!$C$22:$N$22,MOD(C$4-$B32,12)+1) -> 0 | D32: =INDEX(Rules!$C$22:$N$22,MOD(D$4-$B32,12)+1) -> 1 | E32: =INDEX(Rules!$C$22:$N$22,MOD(E$4-$B32,12)+1) -> 0 | F32: =INDEX(Rules!$C$22:$N$22,MOD(F$4-$B32,12)+1) -> 0 | G32: =INDEX(Rules!$C$22:$N$22,MOD(G$4-$B32,12)+1) -> 0 | H32: =INDEX(Rules!$C$22:$N$22,MOD(H$4-$B32,12)+1) -> 0 | I32: =INDEX(Rules!$C$22:$N$22,MOD(I$4-$B32,12)+1) -> 1 | J32: =INDEX(Rules!$C$22:$N$22,MOD(J$4-$B32,12)+1) -> 0 | ... N32: =INDEX(Rules!$C$22:$N$22,MOD(N$4-$B32,12)+1) -> 0 | O32: =SUM(C32:N32) -> 3
A33: Mars | B33: =Ashtakavarga!$C$7 -> 10 | C33: =INDEX(Rules!$C$23:$N$23,MOD(C$4-$B33,12)+1) -> 0 | D33: =INDEX(Rules!$C$23:$N$23,MOD(D$4-$B33,12)+1) -> 1 | E33: =INDEX(Rules!$C$23:$N$23,MOD(E$4-$B33,12)+1) -> 0 | F33: =INDEX(Rules!$C$23:$N$23,MOD(F$4-$B33,12)+1) -> 0 | G33: =INDEX(Rules!$C$23:$N$23,MOD(G$4-$B33,12)+1) -> 1 | H33: =INDEX(Rules!$C$23:$N$23,MOD(H$4-$B33,12)+1) -> 1 | I33: =INDEX(Rules!$C$23:$N$23,MOD(I$4-$B33,12)+1) -> 0 | J33: =INDEX(Rules!$C$23:$N$23,MOD(J$4-$B33,12)+1) -> 1 | ... N33: =INDEX(Rules!$C$23:$N$23,MOD(N$4-$B33,12)+1) -> 1 | O33: =SUM(C33:N33) -> 7
A34: Mercury | B34: =Ashtakavarga!$C$8 -> 0 | C34: =INDEX(Rules!$C$24:$N$24,MOD(C$4-$B34,12)+1) -> 0 | D34: =INDEX(Rules!$C$24:$N$24,MOD(D$4-$B34,12)+1) -> 0 | E34: =INDEX(Rules!$C$24:$N$24,MOD(E$4-$B34,12)+1) -> 1 | F34: =INDEX(Rules!$C$24:$N$24,MOD(F$4-$B34,12)+1) -> 0 | G34: =INDEX(Rules!$C$24:$N$24,MOD(G$4-$B34,12)+1) -> 1 | H34: =INDEX(Rules!$C$24:$N$24,MOD(H$4-$B34,12)+1) -> 1 | I34: =INDEX(Rules!$C$24:$N$24,MOD(I$4-$B34,12)+1) -> 0 | J34: =INDEX(Rules!$C$24:$N$24,MOD(J$4-$B34,12)+1) -> 0 | ... N34: =INDEX(Rules!$C$24:$N$24,MOD(N$4-$B34,12)+1) -> 0 | O34: =SUM(C34:N34) -> 4
A35: Jupiter | B35: =Ashtakavarga!$C$9 -> 2 | C35: =INDEX(Rules!$C$25:$N$25,MOD(C$4-$B35,12)+1) -> 1 | D35: =INDEX(Rules!$C$25:$N$25,MOD(D$4-$B35,12)+1) -> 1 | E35: =INDEX(Rules!$C$25:$N$25,MOD(E$4-$B35,12)+1) -> 0 | F35: =INDEX(Rules!$C$25:$N$25,MOD(F$4-$B35,12)+1) -> 0 | G35: =INDEX(Rules!$C$25:$N$25,MOD(G$4-$B35,12)+1) -> 0 | H35: =INDEX(Rules!$C$25:$N$25,MOD(H$4-$B35,12)+1) -> 0 | I35: =INDEX(Rules!$C$25:$N$25,MOD(I$4-$B35,12)+1) -> 0 | J35: =INDEX(Rules!$C$25:$N$25,MOD(J$4-$B35,12)+1) -> 1 | ... N35: =INDEX(Rules!$C$25:$N$25,MOD(N$4-$B35,12)+1) -> 1 | O35: =SUM(C35:N35) -> 4
A36: Venus | B36: =Ashtakavarga!$C$10 -> 11 | C36: =INDEX(Rules!$C$26:$N$26,MOD(C$4-$B36,12)+1) -> 0 | D36: =INDEX(Rules!$C$26:$N$26,MOD(D$4-$B36,12)+1) -> 0 | E36: =INDEX(Rules!$C$26:$N$26,MOD(E$4-$B36,12)+1) -> 0 | F36: =INDEX(Rules!$C$26:$N$26,MOD(F$4-$B36,12)+1) -> 0 | G36: =INDEX(Rules!$C$26:$N$26,MOD(G$4-$B36,12)+1) -> 1 | H36: =INDEX(Rules!$C$26:$N$26,MOD(H$4-$B36,12)+1) -> 0 | I36: =INDEX(Rules!$C$26:$N$26,MOD(I$4-$B36,12)+1) -> 1 | J36: =INDEX(Rules!$C$26:$N$26,MOD(J$4-$B36,12)+1) -> 0 | ... N36: =INDEX(Rules!$C$26:$N$26,MOD(N$4-$B36,12)+1) -> 0 | O36: =SUM(C36:N36) -> 4
A37: Saturn | B37: =Ashtakavarga!$C$11 -> 9 | C37: =INDEX(Rules!$C$27:$N$27,MOD(C$4-$B37,12)+1) -> 1 | D37: =INDEX(Rules!$C$27:$N$27,MOD(D$4-$B37,12)+1) -> 0 | E37: =INDEX(Rules!$C$27:$N$27,MOD(E$4-$B37,12)+1) -> 0 | F37: =INDEX(Rules!$C$27:$N$27,MOD(F$4-$B37,12)+1) -> 1 | G37: =INDEX(Rules!$C$27:$N$27,MOD(G$4-$B37,12)+1) -> 1 | H37: =INDEX(Rules!$C$27:$N$27,MOD(H$4-$B37,12)+1) -> 1 | I37: =INDEX(Rules!$C$27:$N$27,MOD(I$4-$B37,12)+1) -> 1 | J37: =INDEX(Rules!$C$27:$N$27,MOD(J$4-$B37,12)+1) -> 1 | ... N37: =INDEX(Rules!$C$27:$N$27,MOD(N$4-$B37,12)+1) -> 0 | O37: =SUM(C37:N37) -> 7
A38: Lagna | B38: =Ashtakavarga!$C$12 -> 1 | C38: =INDEX(Rules!$C$28:$N$28,MOD(C$4-$B38,12)+1) -> 0 | D38: =INDEX(Rules!$C$28:$N$28,MOD(D$4-$B38,12)+1) -> 1 | E38: =INDEX(Rules!$C$28:$N$28,MOD(E$4-$B38,12)+1) -> 0 | F38: =INDEX(Rules!$C$28:$N$28,MOD(F$4-$B38,12)+1) -> 1 | G38: =INDEX(Rules!$C$28:$N$28,MOD(G$4-$B38,12)+1) -> 0 | H38: =INDEX(Rules!$C$28:$N$28,MOD(H$4-$B38,12)+1) -> 0 | I38: =INDEX(Rules!$C$28:$N$28,MOD(I$4-$B38,12)+1) -> 1 | J38: =INDEX(Rules!$C$28:$N$28,MOD(J$4-$B38,12)+1) -> 0 | ... N38: =INDEX(Rules!$C$28:$N$28,MOD(N$4-$B38,12)+1) -> 1 | O38: =SUM(C38:N38) -> 5
A39: Mars BAV | C39: =SUM(C31:C38) -> 2 | D39: =SUM(D31:D38) -> 4 | E39: =SUM(E31:E38) -> 1 | F39: =SUM(F31:F38) -> 3 | G39: =SUM(G31:G38) -> 4 | H39: =SUM(H31:H38) -> 4 | I39: =SUM(I31:I38) -> 5 | J39: =SUM(J31:J38) -> 3 | ... N39: =SUM(N31:N38) -> 4 | O39: =SUM(C39:N39) -> 39
A42: Mercury Ashtakavarga (classical total 54) | B42: From sign # | O42: Bindus given
A43: Sun | B43: =Ashtakavarga!$C$5 -> 1 | C43: =INDEX(Rules!$C$29:$N$29,MOD(C$4-$B43,12)+1) -> 1 | D43: =INDEX(Rules!$C$29:$N$29,MOD(D$4-$B43,12)+1) -> 0 | E43: =INDEX(Rules!$C$29:$N$29,MOD(E$4-$B43,12)+1) -> 0 | F43: =INDEX(Rules!$C$29:$N$29,MOD(F$4-$B43,12)+1) -> 0 | G43: =INDEX(Rules!$C$29:$N$29,MOD(G$4-$B43,12)+1) -> 0 | H43: =INDEX(Rules!$C$29:$N$29,MOD(H$4-$B43,12)+1) -> 1 | I43: =INDEX(Rules!$C$29:$N$29,MOD(I$4-$B43,12)+1) -> 1 | J43: =INDEX(Rules!$C$29:$N$29,MOD(J$4-$B43,12)+1) -> 0 | ... N43: =INDEX(Rules!$C$29:$N$29,MOD(N$4-$B43,12)+1) -> 1 | O43: =SUM(C43:N43) -> 5
A44: Moon | B44: =Ashtakavarga!$C$6 -> 8 | C44: =INDEX(Rules!$C$30:$N$30,MOD(C$4-$B44,12)+1) -> 0 | D44: =INDEX(Rules!$C$30:$N$30,MOD(D$4-$B44,12)+1) -> 1 | E44: =INDEX(Rules!$C$30:$N$30,MOD(E$4-$B44,12)+1) -> 0 | F44: =INDEX(Rules!$C$30:$N$30,MOD(F$4-$B44,12)+1) -> 1 | G44: =INDEX(Rules!$C$30:$N$30,MOD(G$4-$B44,12)+1) -> 0 | H44: =INDEX(Rules!$C$30:$N$30,MOD(H$4-$B44,12)+1) -> 1 | I44: =INDEX(Rules!$C$30:$N$30,MOD(I$4-$B44,12)+1) -> 1 | J44: =INDEX(Rules!$C$30:$N$30,MOD(J$4-$B44,12)+1) -> 0 | ... N44: =INDEX(Rules!$C$30:$N$30,MOD(N$4-$B44,12)+1) -> 1 | O44: =SUM(C44:N44) -> 6
A45: Mars | B45: =Ashtakavarga!$C$7 -> 10 | C45: =INDEX(Rules!$C$31:$N$31,MOD(C$4-$B45,12)+1) -> 0 | D45: =INDEX(Rules!$C$31:$N$31,MOD(D$4-$B45,12)+1) -> 1 | E45: =INDEX(Rules!$C$31:$N$31,MOD(E$4-$B45,12)+1) -> 0 | F45: =INDEX(Rules!$C$31:$N$31,MOD(F$4-$B45,12)+1) -> 0 | G45: =INDEX(Rules!$C$31:$N$31,MOD(G$4-$B45,12)+1) -> 1 | H45: =INDEX(Rules!$C$31:$N$31,MOD(H$4-$B45,12)+1) -> 1 | I45: =INDEX(Rules!$C$31:$N$31,MOD(I$4-$B45,12)+1) -> 1 | J45: =INDEX(Rules!$C$31:$N$31,MOD(J$4-$B45,12)+1) -> 1 | ... N45: =INDEX(Rules!$C$31:$N$31,MOD(N$4-$B45,12)+1) -> 1 | O45: =SUM(C45:N45) -> 8
A46: Mercury | B46: =Ashtakavarga!$C$8 -> 0 | C46: =INDEX(Rules!$C$32:$N$32,MOD(C$4-$B46,12)+1) -> 1 | D46: =INDEX(Rules!$C$32:$N$32,MOD(D$4-$B46,12)+1) -> 0 | E46: =INDEX(Rules!$C$32:$N$32,MOD(E$4-$B46,12)+1) -> 1 | F46: =INDEX(Rules!$C$32:$N$32,MOD(F$4-$B46,12)+1) -> 0 | G46: =INDEX(Rules!$C$32:$N$32,MOD(G$4-$B46,12)+1) -> 1 | H46: =INDEX(Rules!$C$32:$N$32,MOD(H$4-$B46,12)+1) -> 1 | I46: =INDEX(Rules!$C$32:$N$32,MOD(I$4-$B46,12)+1) -> 0 | J46: =INDEX(Rules!$C$32:$N$32,MOD(J$4-$B46,12)+1) -> 0 | ... N46: =INDEX(Rules!$C$32:$N$32,MOD(N$4-$B46,12)+1) -> 1 | O46: =SUM(C46:N46) -> 8
A47: Jupiter | B47: =Ashtakavarga!$C$9 -> 2 | C47: =INDEX(Rules!$C$33:$N$33,MOD(C$4-$B47,12)+1) -> 1 | D47: =INDEX(Rules!$C$33:$N$33,MOD(D$4-$B47,12)+1) -> 1 | E47: =INDEX(Rules!$C$33:$N$33,MOD(E$4-$B47,12)+1) -> 0 | F47: =INDEX(Rules!$C$33:$N$33,MOD(F$4-$B47,12)+1) -> 0 | G47: =INDEX(Rules!$C$33:$N$33,MOD(G$4-$B47,12)+1) -> 0 | H47: =INDEX(Rules!$C$33:$N$33,MOD(H$4-$B47,12)+1) -> 0 | I47: =INDEX(Rules!$C$33:$N$33,MOD(I$4-$B47,12)+1) -> 0 | J47: =INDEX(Rules!$C$33:$N$33,MOD(J$4-$B47,12)+1) -> 1 | ... N47: =INDEX(Rules!$C$33:$N$33,MOD(N$4-$B47,12)+1) -> 0 | O47: =SUM(C47:N47) -> 4
A48: Venus | B48: =Ashtakavarga!$C$10 -> 11 | C48: =INDEX(Rules!$C$34:$N$34,MOD(C$4-$B48,12)+1) -> 1 | D48: =INDEX(Rules!$C$34:$N$34,MOD(D$4-$B48,12)+1) -> 1 | E48: =INDEX(Rules!$C$34:$N$34,MOD(E$4-$B48,12)+1) -> 1 | F48: =INDEX(Rules!$C$34:$N$34,MOD(F$4-$B48,12)+1) -> 1 | G48: =INDEX(Rules!$C$34:$N$34,MOD(G$4-$B48,12)+1) -> 0 | H48: =INDEX(Rules!$C$34:$N$34,MOD(H$4-$B48,12)+1) -> 0 | I48: =INDEX(Rules!$C$34:$N$34,MOD(I$4-$B48,12)+1) -> 1 | J48: =INDEX(Rules!$C$34:$N$34,MOD(J$4-$B48,12)+1) -> 1 | ... N48: =INDEX(Rules!$C$34:$N$34,MOD(N$4-$B48,12)+1) -> 1 | O48: =SUM(C48:N48) -> 8
...
