Workbook

Sheet Input
A1: 🪐 VEDIC HOROSCOPE ANALYSIS TOOL
A3: BIRTH DETAILS
A4: Name | B4: Aarav Sharma
A5: Date of Birth | B5: 34926
A6: Time of Birth | B6: 0.40625
A7: Place of Birth | B7: Mumbai
A8: Gender | B8: Male
A10: PLANET POSITIONS (Select Rashi from Dropdown)
A11: Planet | B11: Rashi (Select ▼) | C11: Zodiac # | D11: House # | E11: Degree (0-30) | F11: Retrograde? | G11: Dignity
A12: Lagna (Ascendant) | B12: Simha - Leo | C12: =IF(B12="","",MATCH(LEFT(B12,FIND(" - ",B12)-1),'Reference Data'!B$2:B$13,0)) -> 5 | D12: =IF(C12="","",1) -> 1 | E12: 11.15 | G12: =IF(B12="","","—") -> —
A13: Sun (Surya) | B13: Mesha - Aries | C13: =IF(B13="","",MATCH(LEFT(B13,FIND(" - ",B13)-1),'Reference Data'!B$2:B$13,0)) -> 1 | D13: =IF(C13="","",MOD(C13-$C$12,12)+1) -> 9 | E13: 11.48 | G13: {=IF(B13="","",IF(AND(C13=1,ROUND(E13,0)=10),"⭐ Deep Exalted (10° Mesha)",IF(AND(C13=5,E13>=0,E13<=20),"🌿 Moola Trikona",IF(AND(C13=5,E13>20,E13<=30),"🏠 Own House (Simha)",IF(AND(C13=7,ROUND(E13,0)=10),"💔 Deep Debilitated (10° Tula)",IF(ISNUMBER(SEARCH("Sun",INDEX('Planet Dignity'!$E$2:$E$13,C13))),"⬆ Exalted",IF(ISNUMBER(SEARCH("Sun",INDEX('Planet Dignity'!$F$2:$F$13,C13))),"⬇ Debilitated",IF(INDEX('Planet Dignity'!$C$2:$C$13,C13)="Sun","🏠 Own House","—"))))))))} -> ⬆ Exalted
A14: Moon (Chandra) | B14: Meena - Pisces | C14: =IF(B14="","",MATCH(LEFT(B14,FIND(" - ",B14)-1),'Reference Data'!B$2:B$13,0)) -> 12 | D14: =IF(C14="","",MOD(C14-$C$12,12)+1) -> 8 | E14: 16.56 | G14: {=IF(B14="","",IF(AND(C14=2,ROUND(E14,0)=3),"⭐ Deep Exalted (3° Vrishabha)",IF(AND(C14=2,E14>3,E14<=30),"🌿 Moola Trikona",IF(AND(C14=8,ROUND(E14,0)=3),"💔 Deep Debilitated (3° Vrischika)",IF(ISNUMBER(SEARCH("Moon",INDEX('Planet Dignity'!$E$2:$E$13,C14))),"⬆ Exalted",IF(ISNUMBER(SEARCH("Moon",INDEX('Planet Dignity'!$F$2:$F$13,C14))),"⬇ Debilitated",IF(INDEX('Planet Dignity'!$C$2:$C$13,C14)="Moon","🏠 Own House","—")))))))} -> —
A15: Mars (Mangala) | B15: Mesha - Aries | C15: =IF(B15="","",MATCH(LEFT(B15,FIND(" - ",B15)-1),'Reference Data'!B$2:B$13,0)) -> 1 | D15: =IF(C15="","",MOD(C15-$C$12,12)+1) -> 9 | E15: 27.13 | G15: {=IF(B15="","",IF(AND(C15=10,ROUND(E15,0)=28),"⭐ Deep Exalted (28° Makara)",IF(AND(C15=1,E15>=0,E15<=12),"🌿 Moola Trikona",IF(AND(C15=1,E15>12,E15<=30),"🏠 Own House (Mesha)",IF(C15=8,"🏠 Own House (Vrischika)",IF(AND(C15=4,ROUND(E15,0)=28),"💔 Deep Debilitated (28° Karkataka)",IF(ISNUMBER(SEARCH("Mars",INDEX('Planet Dignity'!$E$2:$E$13,C15))),"⬆ Exalted",IF(ISNUMBER(SEARCH("Mars",INDEX('Planet Dignity'!$F$2:$F$13,C15))),"⬇ Debilitated","—"))))))))} -> 🏠 Own House (Mesha)
A16: Mercury (Budha) | B16: Mesha - Aries | C16: =IF(B16="","",MATCH(LEFT(B16,FIND(" - ",B16)-1),'Reference Data'!B$2:B$13,0)) -> 1 | D16: =IF(C16="","",MOD(C16-$C$12,12)+1) -> 9 | E16: 12.18 | G16: {=IF(B16="","",IF(AND(C16=6,ROUND(E16,0)=15),"⭐ Deep Exalted (15° Kanya)",IF(AND(C16=6,E16>=0,E16<15),"⬆ Exalted (0°–15° Kanya)",IF(AND(C16=6,E16>15,E16<=20),"🌿 Moola Trikona",IF(AND(C16=6,E16>20,E16<=30),"🏠 Own House (Kanya)",IF(C16=3,"🏠 Own House (Mithuna)",IF(AND(C16=12,ROUND(E16,0)=15),"💔 Deep Debilitated (15° Meena)",IF(ISNUMBER(SEARCH("Mercury",INDEX('Planet Dignity'!$E$2:$E$13,C16))),"⬆ Exalted",IF(ISNUMBER(SEARCH("Mercury",INDEX('Planet Dignity'!$F$2:$F$13,C16))),"⬇ Debilitated","—")))))))))} -> —
A17: Jupiter (Guru) | B17: Simha - Leo | C17: =IF(B17="","",MATCH(LEFT(B17,FIND(" - ",B17)-1),'Reference Data'!B$2:B$13,0)) -> 5 | D17: =IF(C17="","",MOD(C17-$C$12,12)+1) -> 1 | E17: 2.26 | G17: {=IF(B17="","",IF(AND(C17=4,ROUND(E17,0)=5),"⭐ Deep Exalted (5° Karkataka)",IF(AND(C17=9,E17>=0,E17<=10),"🌿 Moola Trikona",IF(AND(C17=9,E17>10,E17<=30),"🏠 Own House (Dhanus)",IF(C17=12,"🏠 Own House (Meena)",IF(AND(C17=10,ROUND(E17,0)=5),"💔 Deep Debilitated (5° Makara)",IF(ISNUMBER(SEARCH("Jupiter",INDEX('Planet Dignity'!$E$2:$E$13,C17))),"⬆ Exalted",IF(ISNUMBER(SEARCH("Jupiter",INDEX('Planet Dignity'!$F$2:$F$13,C17))),"⬇ Debilitated","—"))))))))} -> —
A18: Venus (Shukra) | B18: Meena - Pisces | C18: =IF(B18="","",MATCH(LEFT(B18,FIND(" - ",B18)-1),'Reference Data'!B$2:B$13,0)) -> 12 | D18: =IF(C18="","",MOD(C18-$C$12,12)+1) -> 8 | E18: 26.51 | G18: {=IF(B18="","",IF(AND(C18=12,ROUND(E18,0)=27),"⭐ Deep Exalted (27° Meena)",IF(AND(C18=7,E18>=0,E18<=15),"🌿 Moola Trikona",IF(AND(C18=7,E18>15,E18<=30),"🏠 Own House (Tula)",IF(C18=2,"🏠 Own House (Vrishabha)",IF(AND(C18=6,ROUND(E18,0)=27),"💔 Deep Debilitated (27° Kanya)",IF(ISNUMBER(SEARCH("Venus",INDEX('Planet Dignity'!$E$2:$E$13,C18))),"⬆ Exalted",IF(ISNUMBER(SEARCH("Venus",INDEX('Planet Dignity'!$F$2:$F$13,C18))),"⬇ Debilitated","—"))))))))} -> ⭐ Deep Exalted (27° Meena)
A19: Saturn (Shani) | B19: Meena - Pisces | C19: =IF(B19="","",MATCH(LEFT(B19,FIND(" - ",B19)-1),'Reference Data'!B$2:B$13,0)) -> 12 | D19: =IF(C19="","",MOD(C19-$C$12,12)+1) -> 8 | E19: 24.29 | G19: {=IF(B19="","",IF(AND(C19=7,ROUND(E19,0)=20),"⭐ Deep Exalted (20° Tula)",IF(AND(C19=11,E19>=0,E19<=20),"🌿 Moola Trikona",IF(AND(C19=11,E19>20,E19<=30),"🏠 Own House (Kumbha)",IF(C19=10,"🏠 Own House (Makara)",IF(AND(C19=1,ROUND(E19,0)=20),"💔 Deep Debilitated (20° Mesha)",IF(ISNUMBER(SEARCH("Saturn",INDEX('Planet Dignity'!$E$2:$E$13,C19))),"⬆ Exalted",IF(ISNUMBER(SEARCH("Saturn",INDEX('Planet Dignity'!$F$2:$F$13,C19))),"⬇ Debilitated","—"))))))))} -> —
A20: Rahu | B20: Meena - Pisces | C20: =IF(B20="","",MATCH(LEFT(B20,FIND(" - ",B20)-1),'Reference Data'!B$2:B$13,0)) -> 12 | D20: =IF(C20="","",MOD(C20-$C$12,12)+1) -> 8 | E20: 24.28 | G20: {=IF(B20="","",IF(ISNUMBER(SEARCH("Rahu",INDEX('Planet Dignity'!$E$2:$E$13,C20))),"⬆ Exalted",IF(ISNUMBER(SEARCH("Rahu",INDEX('Planet Dignity'!$F$2:$F$13,C20))),"⬇ Debilitated","—")))} -> —
A21: Ketu | B21: Kanya - Virgo | C21: =IF(B21="","",MATCH(LEFT(B21,FIND(" - ",B21)-1),'Reference Data'!B$2:B$13,0)) -> 6 | D21: =IF(C21="","",MOD(C21-$C$12,12)+1) -> 2 | E21: 24.28 | G21: {=IF(B21="","",IF(ISNUMBER(SEARCH("Ketu",INDEX('Planet Dignity'!$E$2:$E$13,C21))),"⬆ Exalted",IF(ISNUMBER(SEARCH("Ketu",INDEX('Planet Dignity'!$F$2:$F$13,C21))),"⬇ Debilitated","—")))} -> —
A23: Instructions:
A24: 1. Enter birth details above (Name, DOB, Time, Place, Gender).
A25: 2. Select Rashi from dropdown for Lagna and each planet. House # auto-calculates relative to Lagna.
A26: 3. Optionally enter degree (0-30) and retrograde status.
A27: 4. Go to the 'Analysis' sheet to see the full automated horoscope report.
A28: 5. Blue cells = Input cells (user editable). House # is auto-computed: House 1 = Lagna rashi.

Sheet Analysis
A1: 🔮 HOROSCOPE ANALYSIS REPORT
A2: =IF(Input!B4="","","Name: "&Input!B4&" | DOB: "&TEXT(Input!B5,"dd-mmm-yyyy")&" | Time: "&TEXT(Input!B6,"hh:mm AM/PM")&" | Place: "&Input!B7) -> Name: Aarav Sharma | DOB: 15-Aug-1995 | Time: 09:45 AM | Place: Mumbai
A4: 1. LAGNA (ASCENDANT) ANALYSIS — Indicates Personality (How the World Sees You)
A5: Characteristic | B5: Value | C5: Explanation
A6: Janma Lagna (Rashi) | B6: =IF(Input!B12="","",LEFT(Input!B12,FIND(" - ",Input!B12)-1)&" ("&MID(Input!B12,FIND(" - ",Input!B12)+3,100)&")") -> Simha (Leo) | C6: The sign rising on the eastern horizon at birth. Determines physical body, outer personality and how others perceive you. Lagna ≠ Mind.
A7: Gender (Odd/Even) | B7: {=IF(Input!C12="","",INDEX('Reference Data'!D$2:D$13,Input!C12))} -> Odd (Male) | C7: Odd = Masculine energy (assertive, active outer demeanor). Even = Feminine energy (receptive, gentle outer demeanor). Describes how you appear to others.
A8: Chara / Sthira / Dwisabhava | B8: {=IF(Input!C12="","",INDEX('Reference Data'!E$2:E$13,Input!C12))} -> Sthira | C8: =IF(B8="","",IF(B8="Chara","Moveable personality: Appears flexible, dynamic, always on the move. Others see you as an achiever.",IF(B8="Sthira","Fixed personality: Appears rigid, determined, stubborn. Others see you as firm and reliable.","Dual personality: Appears adaptable, cautious. Others see you as calculative and flexible."))) -> Fixed personality: Appears rigid, determined, stubborn. Others see you as firm and reliable.
A9: Tatwa (Element) | B9: {=IF(Input!C12="","",INDEX('Reference Data'!F$2:F$13,Input!C12))} -> Agni | C9: =IF(B9="","",IF(B9="Agni","Fire personality: Appears energetic, commanding, assertive. Others see you as a leader and doer.",IF(B9="Vayu","Air personality: Appears intellectual, balanced, creative. Others see you as a thinker.",IF(B9="Prithvi","Earth personality: Appears stable, practical, grounded. Others see you as reliable and hardworking.","Water personality: Appears emotional, compassionate, caring. Others see you as sensitive.")))) -> Fire personality: Appears energetic, commanding, assertive. Others see you as a leader and doer.
A10: Direction | B10: {=IF(Input!C12="","",INDEX('Reference Data'!G$2:G$13,Input!C12))} -> East | C10: Cardinal direction associated with the Lagna rashi. Indicates favorable physical direction for the person.
A11: Varna | B11: {=IF(Input!C12="","",INDEX('Reference Data'!H$2:H$13,Input!C12))} -> Kshatriya | C11: Social standing indicated by Lagna. Used in match-making (Varna Koota). Reflects outward social behavior.
A12: Purushartha | B12: {=IF(Input!C12="","",INDEX('Reference Data'!I$2:I$13,Input!C12))} -> Dharma | C12: =IF(B12="","",IF(B12="Dharma","Dharma Triangle: Outer life oriented towards religion, duty, and righteous actions.",IF(B12="Artha","Artha Triangle: Outer life oriented towards earning, wealth, and material achievement.",IF(B12="Kama","Kama Triangle: Outer life oriented towards desires and their fulfillment.","Moksha Triangle: Outer life oriented towards spiritual liberation and detachment.")))) -> Dharma Triangle: Outer life oriented towards religion, duty, and righteous actions.
A13: Triguna | B13: {=IF(Input!C12="","",INDEX('Reference Data'!J$2:J$13,Input!C12))} -> Sathvik | C13: =IF(B13="","",IF(B13="Sathvik","Sathvik personality: Appears religious, happy, selfless, healthy to others.",IF(B13="Rajasika","Rajasika personality: Appears materialistic, ambitious, proud to others.","Tamasika personality: Appears careless, lazy, dull to others."))) -> Sathvik personality: Appears religious, happy, selfless, healthy to others.
A14: Constitution | B14: {=IF(Input!C12="","",INDEX('Reference Data'!K$2:K$13,Input!C12))} -> Moola | C14: =IF(B14="","",IF(B14="Dhatu","Dhatu: Physical constitution linked to non-living substances (metals, minerals).",IF(B14="Moola","Moola: Physical constitution linked to plant kingdom (rooted, growing).","Jeeva: Physical constitution linked to living beings (animate, active)."))) -> Moola: Physical constitution linked to plant kingdom (rooted, growing).
A15: Fertility | B15: {=IF(Input!C12="","",INDEX('Reference Data'!L$2:L$13,Input!C12))} -> Barren | C15: Physical fertility indicated by Lagna. Fruitful = strong physical vitality. Barren = challenges in physical constitution.
A16: Day/Night Strength | B16: {=IF(Input!C12="","",INDEX('Reference Data'!M$2:M$13,Input!C12))} -> Diurnal | C16: Indicates when the physical body is most energetic. Diurnal = daytime strength. Nocturnal = nighttime strength.
A17: Rising Position | B17: {=IF(Input!C12="","",INDEX('Reference Data'!N$2:N$13,Input!C12))} -> Shirsodaya | C17: Rising position of Lagna rashi. Shirsodaya = head rises first = favorable for physical undertakings.
A18: Tridosha | B18: {=IF(Input!C12="","",INDEX('Reference Data'!P$2:P$13,Input!C12))} -> Pitha | C18: =IF(B18="","",IF(B18="Pitha","Pitha body: Hot physical constitution, strong digestion, prone to inflammation and heat-related ailments.",IF(B18="Vatha","Vatha body: Light physical constitution, prone to joint/nerve issues, dry skin.",IF(B18="Kapha","Kapha body: Heavy physical constitution, calm, prone to congestion and weight gain.","Tridosha body: Balanced physical constitution with all three doshas.")))) -> Pitha body: Hot physical constitution, strong digestion, prone to inflammation and heat-related ailments.
A19: Lucky Colour | B19: {=IF(Input!C12="","",INDEX('Reference Data'!Q$2:Q$13,Input!C12))} -> Off white | C19: Lucky colour for outer appearance and physical well-being. Wearing this colour enhances Lagna strength.
A20: Associated Place | B20: {=IF(Input!C12="","",INDEX('Reference Data'!R$2:R$13,Input!C12))} -> Mountain | C20: Place where the physical body feels most comfortable and energized.
A21: Jyothirlinga | B21: {=IF(Input!C12="","",INDEX('Reference Data'!S$2:S$13,Input!C12))} -> Vaidyanath | C21: Sacred Jyothirlinga associated with this Lagna. Visiting strengthens physical and outer well-being.
A22: Body Part (Kala Purusha) | B22: {=IF(Input!C12="","",INDEX('Reference Data'!T$2:T$13,Input!C12))} -> Heart, Spine, Upper back, Bones, Eyes (Sun's karaka) | C22: Body part of Kala Purusha mapped to this Lagna. Primary health focus area for the physical body.
A23: Personality Traits (Outer Nature) | B23: {=IF(Input!C12="","",INDEX('Reference Data'!U$2:U$13,Input!C12))} -> Energetic, Aggressive, Egoistic, Good in administration, Generous, Dominating, Leaders, Self respect | C23: Core PERSONALITY traits based on Lagna. This is how you behave outwardly, how people describe you, your physical demeanor and approach to life.
A25: 2. JANMA RASHI (MOON SIGN) ANALYSIS — Indicates Mindset (How You Think & Feel Inside)
A26: Characteristic | B26: Value | C26: Explanation
A27: Janma Rashi (Moon Sign) | B27: =IF(Input!B14="","",LEFT(Input!B14,FIND(" - ",Input!B14)-1)&" ("&MID(Input!B14,FIND(" - ",Input!B14)+3,100)&")") -> Meena (Pisces) | C27: The rashi where Moon is placed. Determines the mind, emotions, inner nature, and how you think and feel. Moon ≠ Personality.
A28: Moon Dignity | B28: =IF(Input!C14="","",Input!G14) -> — | C28: Moon exalted in Vrishaba (Taurus) = strong, stable mind. Debilitated in Vrischika (Scorpio) = turbulent, anxious mind.
A29: Mindset & Inner Emotions | B29: {=IF(Input!C14="","",INDEX('Reference Data'!U$2:U$13,Input!C14))} -> Very Moody, Loyal, Loving, Hopeful, Spiritual, Influenced easily, Very emotional, Beautiful, Highly Satvik | C29: Core MINDSET traits based on Moon rashi. This is how you think internally, your emotional patterns, inner reactions, and mental tendencies.
A30: Element (Tatwa) | B30: {=IF(Input!C14="","",INDEX('Reference Data'!F$2:F$13,Input!C14))} -> Jala | C30: =IF(B30="","",IF(B30="Agni","Fire mind: Passionate, energetic thinking, quick temper.",IF(B30="Vayu","Air mind: Intellectual, analytical, restless thoughts.",IF(B30="Prithvi","Earth mind: Practical, grounded, steady emotions.","Water mind: Deep emotions, intuitive, empathetic.")))) -> Water mind: Deep emotions, intuitive, empathetic.
A31: Triguna of Moon Sign | B31: {=IF(Input!C14="","",INDEX('Reference Data'!J$2:J$13,Input!C14))} -> Sathvik | C31: =IF(B31="","",IF(B31="Sathvik","Sathvik mind: Peaceful, religious, content disposition.",IF(B31="Rajasika","Rajasika mind: Ambitious, desire-driven, restless.","Tamasika mind: Prone to inertia, negativity, confusion."))) -> Sathvik mind: Peaceful, religious, content disposition.
A32: Purushartha of Moon Sign | B32: {=IF(Input!C14="","",INDEX('Reference Data'!I$2:I$13,Input!C14))} -> Moksha | C32: =IF(B32="","",IF(B32="Dharma","Mind inclined towards duty, righteousness and moral values.",IF(B32="Artha","Mind focused on wealth accumulation and material security.",IF(B32="Kama","Mind driven by desires, pleasures and fulfillment of wishes.","Mind tends towards spiritual pursuits and liberation.")))) -> Mind tends towards spiritual pursuits and liberation.
A33: Tridosha of Moon Sign | B33: {=IF(Input!C14="","",INDEX('Reference Data'!P$2:P$13,Input!C14))} -> Kapha | C33: Mental health constitution indicated by Moon's rashi. Shows which dosha affects the mind and emotional well-being.
A34: Gender (Odd/Even) of Moon Rashi | B34: {=IF(Input!C14="","",INDEX('Reference Data'!D$2:D$13,Input!C14))} -> Even (Female) | C34: =IF(B34="","",IF(LEFT(B34,3)="Odd","Odd (Masculine) Moon Rashi: Active, assertive mind. Thinks independently, acts quickly.","Even (Feminine) Moon Rashi: Receptive, nurturing mind. Listens first, empathizes naturally.")) -> Even (Feminine) Moon Rashi: Receptive, nurturing mind. Listens first, empathizes naturally.
A35: Chara/Sthira/Dwisabhava of Moon Rashi | B35: {=IF(Input!C14="","",INDEX('Reference Data'!E$2:E$13,Input!C14))} -> Dwisabhava | C35: =IF(B35="","",IF(B35="Chara","Moveable Moon: Mind is dynamic, restless, craves change and new experiences.",IF(B35="Sthira","Fixed Moon: Mind is steady, persistent, emotionally rigid, dislikes change.","Dual Moon: Mind oscillates between options, adaptable but sometimes indecisive."))) -> Dual Moon: Mind oscillates between options, adaptable but sometimes indecisive.
A36: Direction of Moon Rashi | B36: {=IF(Input!C14="","",INDEX('Reference Data'!G$2:G$13,Input!C14))} -> North | C36: Direction the mind is drawn towards. In Prashna, indicates where a missing object or person may be found.
A37: Varna of Moon Rashi | B37: {=IF(Input!C14="","",INDEX('Reference Data'!H$2:H$13,Input!C14))} -> Brahmin | C37: =IF(B37="","",IF(B37="Brahmin","Brahmin Moon: Mind inclined towards knowledge, teaching, spirituality and learning.",IF(B37="Kshatriya","Kshatriya Moon: Mind inclined towards leadership, courage, protecting others.",IF(B37="Vaishya","Vaishya Moon: Mind inclined towards trade, negotiation, practical thinking.","Shudra Moon: Mind inclined towards service, craftsmanship, humility.")))) -> Brahmin Moon: Mind inclined towards knowledge, teaching, spirituality and learning.
A38: Constitution of Moon Rashi | B38: {=IF(Input!C14="","",INDEX('Reference Data'!K$2:K$13,Input!C14))} -> Jeeva | C38: =IF(B38="","",IF(B38="Dhatu","Dhatu Moon: Mind attracted to material objects, practical security, tangible outcomes.",IF(B38="Moola","Moola Moon: Mind connected to nature, growth, rooted thinking, organic processes.","Jeeva Moon: Mind oriented towards living beings, relationships, empathy, social bonds."))) -> Jeeva Moon: Mind oriented towards living beings, relationships, empathy, social bonds.
A39: Fertility of Moon Rashi | B39: {=IF(Input!C14="","",INDEX('Reference Data'!L$2:L$13,Input!C14))} -> Fruitful | C39: =IF(B39="","",IF(B39="Fruitful","Fruitful Moon: Emotionally abundant, nurturing, good for fertility and creative thinking.",IF(B39="Barren","Barren Moon: Emotionally restrained, may suppress feelings, analytical over emotional.","Semi-fruitful Moon: Moderate emotional expression, balanced between nurturing and restraint."))) -> Fruitful Moon: Emotionally abundant, nurturing, good for fertility and creative thinking.
A40: Day/Night Strength of Moon Rashi | B40: {=IF(Input!C14="","",INDEX('Reference Data'!M$2:M$13,Input!C14))} -> Diurnal | C40: =IF(B40="","",IF(B40="Nocturnal","Nocturnal Moon: Mind is strongest at night, creative in solitude, introspective, imaginative.","Diurnal Moon: Mind is sharpest during the day, thrives in social settings, action-oriented.")) -> Diurnal Moon: Mind is sharpest during the day, thrives in social settings, action-oriented.
A41: Rising Position of Moon Rashi | B41: {=IF(Input!C14="","",INDEX('Reference Data'!N$2:N$13,Input!C14))} -> Ubhadaya | C41: =IF(B41="","",IF(B41="Shirsodaya","Shirsodaya Moon: Thoughts lead to success, favorable for mental queries and decisions.",IF(B41="Prushtodaya","Prushtodaya Moon: Slow to reveal results, patience needed for mental endeavors.","Ubhayodaya Moon: Mixed rising, results depend on supporting planets."))) -> Ubhayodaya Moon: Mixed rising, results depend on supporting planets.
A42: Lucky Colour of Moon Rashi | B42: {=IF(Input!C14="","",INDEX('Reference Data'!Q$2:Q$13,Input!C14))} -> White | C42: Wearing or surrounding yourself with this colour calms the mind and enhances Moon's positive effects.
...

Sheet Reference Data
A1: House | B1: Sanskrit Name | C1: English Name | D1: Odd/Even | E1: Chara/Sthira/Dwisabhava | F1: Tatwa (Element) | G1: Direction | H1: Varna | I1: Purushartha | J1: Triguna | K1: Constitution | L1: Fertility | M1: Day/Night | N1: Rising Position | O1: Legs | P1: Tridosha | Q1: Colour | R1: Place | S1: Jyothirlinga | T1: Body Part | U1: Mindset / Personality
A2: 1 | B2: Mesha | C2: Aries | D2: Odd (Male) | E2: Chara | F2: Agni | G2: East | H2: Kshatriya | I2: Dharma | J2: Rajasika | K2: Dhatu | L2: Barren | M2: Nocturnal | N2: Prushtodaya | O2: Chatuspada | P2: Pitha | Q2: Red | R2: Forest | S2: Rameshwaram | T2: Head, Brain, Skull | U2: Energetic, Active, Aggressive, Initiative, Impulsive, Restless, Bold, Wants to Lead
A3: 2 | B3: Vrishaba | C3: Taurus | D3: Even (Female) | E3: Sthira | F3: Prithvi | G3: South | H3: Vysya | I3: Artha | J3: Rajasika | K3: Moola | L3: Semi Fruitful | M3: Nocturnal | N3: Prushtodaya | O3: Chatuspada | P3: Vatha | Q3: White | R3: Agricultural land | S3: Somnatheshwara | T3: Face, Eyes (right), Mouth, Throat, Vocal cords | U3: Stability, Focused, Practical, Patience, Nourishment, Charming, Stubborn
A4: 3 | B4: Mithuna | C4: Gemini | D4: Odd (Male) | E4: Dwisabhava | F4: Vayu | G4: West | H4: Shudra | I4: Kama | J4: Rajasika | K4: Jeeva | L4: Barren | M4: Nocturnal | N4: Shirsodaya | O4: Dwipada | P4: Tridosha | Q4: Green | R4: Bedroom | S4: Nageshwara | T4: Neck, Shoulders, Arms, Hands, Lungs (upper), Nervous system | U4: Good communication, Intelligent, Artistic, Humorous, Multitasking, Creative, Adaptable, Fickle minded
A5: 4 | B5: Karkataka | C5: Cancer | D5: Even (Female) | E5: Chara | F5: Jala | G5: North | H5: Brahmin | I5: Moksha | J5: Sathvik | K5: Dhatu | L5: Fruitful | M5: Nocturnal | N5: Prushtodaya | O5: Jalachara | P5: Kapha | Q5: Pink | R5: River | S5: Omkareshwara | T5: Chest, Lungs, Breasts, Ribcage, Stomach (upper) | U5: Emotional, Sensitive, Honest, Mood swings, Motherly nature, Peace loving, Nurturing, Psychic
A6: 5 | B6: Simha | C6: Leo | D6: Odd (Male) | E6: Sthira | F6: Agni | G6: East | H6: Kshatriya | I6: Dharma | J6: Sathvik | K6: Moola | L6: Barren | M6: Diurnal | N6: Shirsodaya | O6: Vanachara | P6: Pitha | Q6: Off white | R6: Mountain | S6: Vaidyanath | T6: Heart, Spine, Upper back, Bones, Eyes (Sun's karaka) | U6: Energetic, Aggressive, Egoistic, Good in administration, Generous, Dominating, Leaders, Self respect
A7: 6 | B7: Kanya | C7: Virgo | D7: Even (Female) | E7: Dwisabhava | F7: Prithvi | G7: South | H7: Vysya | I7: Artha | J7: Tamasika | K7: Jeeva | L7: Barren | M7: Diurnal | N7: Shirsodaya | O7: Dwipada | P7: Vatha | Q7: Variegated | R7: Gardens | S7: Mallikarjuna | T7: Stomach (lower), Intestines, Digestive system, Abdomen, Navel | U7: Practical, Critical, Perfectionist, Cleanliness, Observant, Intelligent, Reserved, Organised, Analytical
A8: 7 | B8: Tula | C8: Libra | D8: Odd (Male) | E8: Chara | F8: Vayu | G8: West | H8: Shudra | I8: Kama | J8: Rajasika | K8: Dhatu | L8: Semi Fruitful | M8: Diurnal | N8: Shirsodaya | O8: Dwipada | P8: Vatha | Q8: Black | R8: Business Place | S8: Mahakaleshwar | T8: Lower abdomen, Kidneys, Lumbar region, Lower back, Skin | U8: Attractive, Extroverts, Well Mannered, Peace makers, Diplomatic, Good negotiators, Business minded
A9: 8 | B9: Vrischika | C9: Scorpio | D9: Even (Female) | E9: Sthira | F9: Jala | G9: North | H9: Brahmin | I9: Moksha | J9: Rajasika | K9: Moola | L9: Fruitful | M9: Diurnal | N9: Shirsodaya | O9: Keeta | P9: Kapha | Q9: Saffron | R9: Hole / Cavity | S9: Grishneshwar | T9: Reproductive organs, Genitals, Bladder, Excretory system, Pelvis | U9: Secretive, Pessimistic, Possessive, Good researchers, Revenge, Mood swings, Good imagination, Anxiety
A10: 9 | B10: Dhanur | C10: Sagittarius | D10: Odd (Male) | E10: Dwisabhava | F10: Agni | G10: East | H10: Kshatriya | I10: Dharma | J10: Sathvik | K10: Jeeva | L10: Semi Fruitful | M10: Nocturnal | N10: Prushtodaya | O10: Dwipada 1st / Chatuspada 2nd | P10: Pitha | Q10: Golden | R10: Palace | S10: Kashi Vishwanath | T10: Thighs, Hips, Liver, Arterial system | U10: Fun Loving, Adventurous, Very Optimistic, Confident, Attractive, Traditional, Active, Competitive
A11: 10 | B11: Makara | C11: Capricorn | D11: Even (Female) | E11: Chara | F11: Prithvi | G11: South | H11: Vysya | I11: Artha | J11: Tamasika | K11: Dhatu | L11: Semi Fruitful | M11: Nocturnal | N11: Prushtodaya | O11: Chatuspada 1st / Jalachara 2nd | P11: Vatha | Q11: Various colours | R11: Marshlands | S11: Bhima Shankara | T11: Knees, Joints, Bones (lower body), Skin | U11: Hard Workers, Straight Forward, Methodical, Ambitious, Practical, Rational, Perfectionist, Calculative
A12: 11 | B12: Kumbha | C12: Aquarius | D12: Odd (Male) | E12: Sthira | F12: Vayu | G12: West | H12: Shudra | I12: Kama | J12: Tamasika | K12: Moola | L12: Semi Fruitful | M12: Diurnal | N12: Shirsodaya | O12: Dwipada | P12: Vatha | Q12: Dark Brown | R12: Potters Place | S12: Kedarnath | T12: Calves, Ankles, Shins, Circulatory system | U12: Sharp and quick, Emotional detachment, Stubborn, Mature, Creative, Friendly, Scientific, Philosophical, Rebel
A13: 12 | B13: Meena | C13: Pisces | D13: Even (Female) | E13: Dwisabhava | F13: Jala | G13: North | H13: Brahmin | I13: Moksha | J13: Sathvik | K13: Jeeva | L13: Fruitful | M13: Diurnal | N13: Ubhadaya | O13: Jalachara | P13: Kapha | Q13: White | R13: Ocean | S13: Tryambakeshwar | T13: Feet, Toes, Lymphatic system | U13: Very Moody, Loyal, Loving, Hopeful, Spiritual, Influenced easily, Very emotional, Beautiful, Highly Satvik

Sheet Planet Dignity
A1: House # | B1: Rashi | C1: Lord | D1: MTR | E1: Exalted Planet | F1: Debilitated Planet | G1: Deep Exaltation Degree | H1: Deep Debilitation Degree | I1: Moola Trikona Range | J1: Own House (Swakshetra)
A2: 1 | B2: Aries | C2: Mars | D2: Yes | E2: Sun | F2: Saturn | G2: 10° (Sun) | H2: 20° (Saturn) | I2: 0°–12° Mesha (Mars) | J2: 12°–30° Mesha (Mars)
A3: 2 | B3: Taurus | C3: Venus | D3: Yes | E3: Rahu, Moon | F3: Ketu | G3: 3° (Moon) | I3: 3°–30° Vrishabha (Moon) | J3: Vrishabha (Venus)
A4: 3 | B4: Gemini | C4: Mercury | J4: Mithuna (Mercury)
A5: 4 | B5: Cancer | C5: Moon | E5: Jupiter | F5: Mars | G5: 5° (Jupiter) | H5: 28° (Mars) | J5: Karkataka (Moon)
A6: 5 | B6: Leo | C6: Sun | D6: Yes | I6: 0°–20° Simha (Sun) | J6: 20°–30° Simha (Sun)
A7: 6 | B7: Virgo | C7: Mercury | D7: Yes | E7: Mercury | F7: Venus | G7: 15° (Mercury) | H7: 27° (Venus) | I7: 16°–20° Kanya (Mercury) | J7: 20°–30° Kanya (Mercury)
A8: 7 | B8: Libra | C8: Venus | D8: Yes | E8: Saturn | F8: Sun | G8: 20° (Saturn) | H8: 10° (Sun) | I8: 0°–15° Tula (Venus) | J8: 15°–30° Tula (Venus)
A9: 8 | B9: Scorpio | C9: Mars | E9: Ketu | F9: Rahu, Moon | H9: 3° (Moon) | J9: Vrischika (Mars)
A10: 9 | B10: Sagittarius | C10: Jupiter | D10: Yes | I10: 0°–10° Dhanus (Jupiter) | J10: 10°–30° Dhanus (Jupiter)
A11: 10 | B11: Capricorn | C11: Saturn | E11: Mars | F11: Jupiter | G11: 28° (Mars) | H11: 5° (Jupiter) | J11: Makara (Saturn)
A12: 11 | B12: Aquarius | C12: Saturn | D12: Yes | I12: 0°–20° Kumbha (Saturn) | J12: 20°–30° Kumbha (Saturn)
A13: 12 | B13: Pisces | C13: Jupiter | E13: Venus | F13: Mercury | G13: 27° (Venus) | H13: 15° (Mercury) | J13: Meena (Jupiter)
A16: STHANA BALA — SUN (from Session 6)
A17: Position | B17: Rashi / Degree | C17: Sanskrit Name | D17: Strength %
A18: Exaltation (Uchha) | B18: Mesha · deep point 10° | C18: Garvita / Deepta | D18: 1
A19: Moola Trikona | B19: 0°–20° Simha | C19: Sukitha | D19: 0.75
A20: Own House | B20: 20°–30° Simha | C20: Swastha | D20: 0.5
A21: Friend's House | B21: — | C21: Mudita / Shantha | D21: Moderate
A22: Neutral House | B22: — | C22: Neutral | D22: Moderate
A23: Enemy's House | B23: — | C23: Dukitha | D23: Low
A24: Debilitation (Neecha) | B24: Tula · deep point 10° | C24: Deena / Susupti | D24: Lowest
A26: COMBUSTION RULE
A27: Combust range = within 5° of the Sun on either side (a 10° window). A planet this close to the Sun loses its lustre and is weakened — Astangata (combustion). Applies to Moon, Mars, Mercury, Jupiter, Venus and Saturn only; the Sun itself and the nodes Rahu & Ketu are not subject to combustion.
A29: STHANA BALA — MOON (Positional Strength)
A30: SL | B30: Position (Sthana) | C30: Avastha | D30: Rashi / Degree | E30: Quantum of Strength
A31: 1 | B31: Exaltation (Uchha) | C31: Garvita (Proud), Deepta (Bright) | D31: 3° Vrishabha | E31: 1
A32: 2 | B32: Moola Trikona | C32: Sukitha | D32: 3°–30° Vrishabha | E32: 0.75
A33: 3 | B33: Own House (Swakshetra) | C33: Swastha (Content) | D33: Karkataka | E33: 0.5
A34: 4 | B34: Friend's House | C34: Mudita (Delighted), Shantha (Peaceful) | D34: — | E34: 0.25
A35: 5 | B35: Neutral House | C35: — | D35: — | E35: 0.125
A36: 6 | B36: Enemy's House | C36: Dukitha (Sad) | D36: — | E36: 0
A37: 7 | B37: Debilitation (Neecha) | C37: Deena (Distressed), Susupti (Sleeping) | D37: 3° Vrischika | E37: 0
A39: Note: Row 1 = Strongest, Row 7 = Weakest. Same scale applies to other planets — only the rashis change.
A41: STHANA BALA — JUPITER (Positional Strength)
A42: SL | B42: Position (Sthana) | C42: Avastha | D42: Rashi / Degree | E42: Quantum of Strength
A43: 1 | B43: Exaltation (Uchha) | C43: Garvita (Proud), Deepta (Bright) | D43: 5° Karkataka | E43: 1
A44: 2 | B44: Moola Trikona | C44: Sukitha | D44: 0°–10° Dhanur | E44: 0.75
A45: 3 | B45: Own House (Swakshetra) | C45: Swastha (Content) | D45: 10°–30° Dhanur & full Meena | E45: 0.5
A46: 4 | B46: Friend's House | C46: Mudita (Delighted), Shantha (Peaceful) | D46: — | E46: 0.25
...

Sheet Planet Characteristics
A1: PLANET CHARACTERISTICS — MASTER TABLE
A2: Sun details populated from Session 6. Other planets will be filled in as future sessions cover them.
A4: Characteristic | B4: Sun ☉ | C4: Moon ☽ | D4: Mars ♂ | E4: Mercury ☿ | F4: Jupiter ♃ | G4: Venus ♀ | H4: Saturn ♄ | I4: Rahu ☊ | J4: Ketu ☋
A6: BASIC IDENTITY
A7: Sanskrit Name | B7: Surya / Ravi | C7: Chandra | D7: Mangala / Kuja | E7: Budha | F7: Guru / Brihaspati | G7: Shukra | H7: Shani | I7: Rahu | J7: Ketu
A8: Symbol | B8: ☉ | C8: ☽ | D8: ♂ | E8: ☿ | F8: ♃ | G8: ♀ | H8: ♄ | I8: ☊ | J8: ☋
A9: English Name | B9: Sun | C9: Moon | D9: Mars | E9: Mercury | F9: Jupiter | G9: Venus | H9: Saturn | I9: Ascending Node / Dragon Head | J9: Descending Node / Dragon Tail
A10: Inner / Outer | B10: Inner | C10: Inner | D10: Outer | E10: Inner | F10: Outer | G10: Inner | H10: Outer | I10: Shadow planet | J10: Shadow planet
A12: MOVEMENT
A13: Days per Rashi | B13: ~30 days | C13: ~2¼ days | D13: ~45–49 days | E13: ~24 days | F13: ~1 year | G13: ~25–27 days | H13: ~2½ years | I13: ~1½ years | J13: ~1½ years
A14: Time for Full Zodiac | B14: ~1 year | C14: ~27 days | D14: ~1½ years | E14: ~288 days | F14: ~12 years | G14: ~324 days | H14: ~30 years | I14: ~18 years | J14: ~18 years
A15: Direction of Motion | B15: Direct | C15: Direct | D15: Direct (occ. retrograde) | E15: Direct (occ. retrograde) | F15: Direct (occ. retrograde) | G15: Direct (occ. retrograde) | H15: Direct (occ. retrograde) | I15: Always Retrograde | J15: Always Retrograde
A16: Aspects (Drishti) | B16: 7th only (Inner) | C16: 7th only (Inner) | D16: 4th, 7th, 8th | E16: 7th only (Saptama Drishti / Opposition, 180°) | F16: 5th, 7th, 9th | G16: 7th only (Inner) | H16: 3rd, 7th, 10th | I16: (later session) | J16: (later session)
A18: DIGNITY / STHANA BALA
A19: Exaltation Rashi | B19: Mesha | C19: Vrishabha | D19: Makara | E19: Kanya | F19: Karkataka | G19: Meena | H19: Tula | I19: Vrishabha | J19: Vrischika
A20: Deep Exaltation Degree | B20: 10° Mesha | C20: 3° Vrishabha | D20: 28° Makara | E20: 15° Kanya | F20: 5° Karkataka | G20: 27° Meena | H20: 20° Tula | I20: (later session) | J20: (later session)
A21: Debilitation Rashi | B21: Tula | C21: Vrischika | D21: Karkataka | E21: Meena | F21: Makara | G21: Kanya | H21: Mesha | I21: Vrischika | J21: Vrishabha
A22: Deep Debilitation Degree | B22: 10° Tula | C22: 3° Vrischika | D22: 28° Karkataka | E22: 15° Meena | F22: 5° Makara | G22: 27° Kanya | H22: 20° Mesha | I22: (later session) | J22: (later session)
A23: Moola Trikona Range | B23: 0°–20° Simha | C23: 3°–30° Vrishabha | D23: 0°–12° Mesha | E23: 15°–20° Kanya | F23: 0°–10° Dhanur | G23: 0°–15° Tula | H23: 0°–20° Kumbha | I23: — (no MTR) | J23: — (no MTR)
A24: Own House (Swakshetra) | B24: Simha | C24: Karkataka | D24: Mesha, Vrischika | E24: Mithuna; Kanya (20°–30°) | F24: Dhanur, Meena | G24: Vrishabha, Tula | H24: Makara, Kumbha | I24: — (no rulership) | J24: — (no rulership)
A26: KARAKATWAS (SIGNIFICATIONS)
A27: Soul / Mind / Body | B27: Soul (Atma) | C27: Mind (Manas), Emotions | D27: Protection (Key Word); Courage, Energy, Action | E27: Connection (Key Word); Intelligence, Knowledge / Information | F27: Wisdom & Knowledge (Gnana Karaka); Auspiciousness, Expansion, Divinity | G27: Pleasure & Love (Bhoga Karaka); Beauty, Romance, Artistic talent, Luxury | H27: Body / Longevity (Ayus); dispenser of Karma | I27: (later session) | J27: (later session)
A28: Relationships (Karaka of) | B28: Father, Father-in-law | C28: Mother, Mother-in-law, Elderly ladies | D28: Younger Brother | E28: Maternal Uncle, Boy friend, Girl friend, Lover, Brokers | F28: Children (Putra / Santana Karaka), Grandchildren, Elder Brother, Teachers | G28: Spouse / Wife (Kalatra Karaka), Daughter, Daughter-in-law, Aunt | H28: Elder brother, elderly & poor people, servants, handicapped, masses, employees | I28: (later session) | J28: (later session)
A29: Profession / Status | B29: Authority, Government, Leadership, Boss, Administration, Management, Influential persons | C29: Travel agent, Agriculture, Hotel Industry, Nurse, Sailor, Dairy business, Grocery shop, Edible oil merchant, BWSSB | D29: Commander in Chief; Dentist, Surgeon, Mechanic, Army, Security, Police, Fire engine dept, Supervisor, Engineer | E29: Prince (Portfolio); Teacher, Writer, Author, Broker, Publisher, Public speaker, Journalist, Trader, Ambassador, Accountant, Book seller | F29: DevaGuru / Minister (Portfolio); Priest, Banker, Judge, Teacher, Counsellor, Financier, Auditor, Bullion trader | G29: Asura Guru / Shukracharya (Portfolio); Beautician, Costume designer, Artist, Musician, Singer, Dancer, Poet, Painter, Jeweller, Silk trader, Hotel & Event Management | H29: Servants, labourers, cleaners, cobblers, iron/oil merchants, jailors, coffin makers, waste disposal | I29: (later session) | J29: (later session)
A30: Reputation | B30: Name & Fame, Reputation, Visibility, Permanent Income | C30: Queen (Portfolio); emotional reputation; popularity with public | D30: Bhoomi Karaka — Landed property; recognition through valour | E30: Reputation through communication, speech, intellect and business | F30: Honour & Respect (Gauravam); reputation through wisdom, wealth (Dhana Karaka) and benevolence | G30: Reputation through beauty, artistic talent, luxury and charm | H30: Earned slowly through hard work; humble / low status | I30: (later session) | J30: (later session)
A31: Personality Traits | B31: Ego, Vitality, Open-hearted, Equality, Generous, High Expectations, Punctual, Vertical | C31: Gentle, soft, caring, emotional; feminine energy; sensitive; imaginative; changes quickly like emotions | D31: Courageous, Aggressive, Energetic / Action-oriented, Adventurous, Hasty & Quick / Dynamic, Impulsive, Faithful, Egoistic / Arrogant, Stubborn / Dominating, Quarrelsome, Anger, Retaliating | E31: Intelligent, Educated, Knowledgeable, Speech-oriented, Business-minded, Friendly & Fun-loving, Cunning / Tricky, Diplomatic, Calculative, Smart, Adaptable | F31: Wise, Knowledgeable, Benevolent, Optimistic, Respectable, Generous, Spiritual, Just, Expansive | G31: Pleasant, Artistic, Romantic, Charming, Sensual, Luxury-loving, Beauty-conscious, Refined | H31: If strong: patient, disciplined, hardworking, philosophical. If weak: lazy, melancholic, inferiority complex | I31: (later session) | J31: (later session)
A32: Body Parts Ruled | B32: Eyes, Heart, Spine, Bones | C32: Left eye, Breast, Heart, Mind, Uterus, Urinary bladder | D32: Muscle, Bone marrow, RBC, Eyebrow, Teeth, Menstrual cycle | E32: Skin, Nerves, Tongue, Throat, Neck, Shoulder, Hands, Little finger, Forehead | F32: Liver, Pancreas, Gall bladder, Stomach, Thighs, Index finger, Nose, Fat, Ear | G32: Cheeks, Semen / Reproductive fluids, Kidneys, Luster of the eyes | H32: Chin, middle finger, knees, knee-caps, buttocks, foreleg, feet | I32: (later session) | J32: (later session)
A33: Constitution (Tridosha) | B33: Pitta (Hot) | C33: Kapha | D33: Pitta (Bile) | E33: Vatha (Wind) | F33: Vatha (Wind) | G33: Kapha (Phlegmatic) | H33: Vatha | I33: (later session) | J33: (later session)
A34: General Health Indicator | B34: General Health, Vitality | C34: Mental health, fluids, immunity; Diseases: Cold, Cough, Phlegm, Mental disorders, Sinus, Swellings | D34: Diseases: Cuts, Wounds, Bleeding, BP, Piles, Anemia, Accidents | E34: Diseases: Skin disease, Itches, Sore throat, Tonsils, Dumbness, Leprosy | F34: Diseases: Jaundice, Liver complaints, Diabetes, Indigestion, Obesity, Flatulence | G34: Diseases: Diabetes, Kidney / Bladder stones, Urinary & hormonal disorders, Thyroid, Venereal diseases | H34: Arthritis, chronic ailments, constipation, rheumatism, defective limbs, lethargy | I34: (later session) | J34: (later session)
A35: Nature | B35: Separative planet; causes combustion to nearby planets | C35: Benefic (when waxing/strong); feminine; water element; rules Karkataka | D35: Malefic; fiery; outer planet; karaka of energy, accidents, electricity, machinery, volcanic eruption | E35: Neutral planet — takes the nature of the planet it associates with; Rajasic; karaka of communication and intellect | F35: Most benevolent planet — greatest natural benefic (Subha Graha); Sathwik; Akasha tatwa | G35: Natural benefic; karaka of luxury, love & material comforts; Rajasic; Jala tatwa | H35: Natural Malefic; Karma Phala Daata (hard task-master) | I35: (later session) | J35: (later session)
A37: MYTHOLOGY / DEITY
A38: Dasha Avatara | B38: Lord Rama | C38: Lord Krishna | D38: Lord Narasimha | E38: Buddha (Balarama) | F38: Vamana | G38: Parashurama | H38: Koorma (Tortoise) | I38: (later session) | J38: (later session)
A39: Birthday (Tithi) | B39: Prabhava Samvatsara, Magha Masa, Shukla Sapthami | C39: Nandana Samvatsara, Karthika Masa, Shukla Pournami | D39: Akshaya Samvatsara, Shravana Masa, Shukla Trayodashi | E39: Soumya Samvatsara, Jyeshta Masa, Krishna Ekadashi | F39: Angirasa Samvatsara, Vaishaka Masa, Shukla Ekadashi | G39: Manmatha Samvatsara, Chaitra Masa, Shukla Ekadashi | H39: Vibhava Samvatsara, Jyeshta Masa, Krishna Paksha – Amavasya | I39: (later session) | J39: (later session)
A40: Gothra | B40: Kashyapa | C40: Atreya | D40: Bharadwaja | E40: Atreya | F40: Angirasa | G40: Bhargava | H40: Kashyapa | I40: (later session) | J40: (later session)
A41: Consorts / Wives | B41: Sanjna & Chaya | C41: 27 Nakshatras (Rohini is his favourite) | D41: Shakthi | E41: Gnaani | F41: Tara | G41: Sukeerthi | H41: Jyeshta Devi | I41: (later session) | J41: (later session)
A42: Vehicle (Vahana) | B42: 7 horses | C42: Sea Horse | D42: Red Ram | E42: Yellow Lion | F42: (later session) | G42: (later session) | H42: Crow / Buffalo | I42: (later session) | J42: (later session)
A43: Numerology Number | B43: 1 | C43: 2 | D43: 9 | E43: 5 | F43: 3 | G43: 6 | H43: 8 | I43: (later session) | J43: (later session)
A44: Combustion Effect (when combust by Sun) | B44: — (Sun is the combustor) | C44: Mind filled with ego; cannot think clearly | D44: Overconfident; feels can beat anyone | E44: Feels most intelligent | F44: Feels he knows everything; no need of Guru/God | G44: Unnecessary expenses on comforts, pleasures, entertainment | H44: Postpones work; thinks can finish in time even if late | I44: (later session) | J44: (later session)
A46: MOON — EXTENDED KARAKATWAS
A47: Portfolio | C47: Queen | D47: Commander in Chief | E47: Prince | F47: DevaGuru (Minister) | G47: Asura Guru (Shukracharya) | H47: Servants
...

Sheet Guide & Explanations
A1: 📚 GUIDE & EXPLANATIONS
A3: TATWA (ELEMENTS) — Agni / Vayu / Prithvi / Jala
A4: Usage | B4: 1) Used for Pariharas: Homa/lamps for Agni; Abhisheka/Teertha for Jala; Chanting Mantras for Vayu; Charity for Prithvi. 2) Used to check for natural calamities in Mundane Astrology.
A6: Agni (Fire) | B6: Energetic, hot, active, strong will, assertive, independent, likes popularity, sometimes dominating, likes to be in position.
A7: Vayu (Air) | B7: Creative, intellectual, logical, good planners, balanced, nervous.
A8: Prithvi (Earth) | B8: Perseverance, stability, hard work, materialistic, practical, self-centered, stubborn.
A9: Jala (Water) | B9: Emotional, devotional, compassionate, receptive, intuitive, psychic, suspicious.
A11: Agni Sub-Types | B11: Mesha Agni = Forest fire (wild, spreads rapidly). Simha Agni = Kitchen fire (used for cooking, productive purpose). Dhanur Agni = Homa fire (spiritual awakening).
A13: Jala Sub-Types | B13: Karkataka Jala = Pure water like Ganga (nourishes). Vrischika Jala = Polluted/deep waters. Meena Jala = Ocean water.
A15: Prithvi Sub-Types | B15: Vrishabha = Agricultural land (bull used for tilling). Kanya = Garden (young lady who loves flowers). Makara = Marshy land (crocodile symbol).
A17: Vayu Sub-Types | B17: Mithuna = Intelligence used in communication (to impress, symbol = Male & Female). Tula = Intelligence used in business (symbol = Balance). Kumbha = Intelligence used in creativity.
A19: CHARA / STHIRA / DWISABHAVA
A20: Chara (Moveable) | B20: Mesha, Karkataka, Tula, Makara — Flexible, adaptable, dynamic, achievers.
A21: Sthira (Fixed) | B21: Vrishabha, Simha, Vrischika, Kumbha — Rigid, firm on decisions, stubborn, determined, impractical.
A22: Dwisabhava (Dual) | B22: Mithuna, Kanya, Dhanur, Meena — Flexible or rigid depending on situation, indecisive, too cautious, calculative.
A23: Note | B23: If more planets are in Chara Rashis, the person travels always. In Sthira rashis, will stay at one place.
A25: VARNA
A26: Usage | B26: Used in Match Making (Varna Koota). Male should be of higher varna than female. If both same varna, very good.
A28: PURUSHARTHAS
A29: Dharma | B29: Dharma Triangle (Mesha, Simha, Dhanur): Tendency towards religion and righteous deeds.
A30: Artha | B30: Artha Triangle (Vrishabha, Kanya, Makara): Tendency towards earning and accumulating wealth.
A31: Kama | B31: Kama Triangle (Mithuna, Tula, Kumbha): How successful in achieving desires.
A32: Moksha | B32: Moksha Triangle (Karkataka, Vrischika, Meena): Extent of achieving liberation.
A34: TRIGUNAS
A35: Sathvik | B35: Religious, happy, work without expecting anything in return, sacrifice, healthy.
A36: Rajasika | B36: Materialistic, desires, lust, proud.
A37: Tamasika | B37: Carelessness, laziness, anger, dull headed.
A39: CONSTITUTION (DHATU / MOOLA / JEEVA)
A40: Dhatu | B40: Non-living objects like metals, mineral objects.
A41: Moola | B41: Living objects which have life but no movement like trees.
A42: Jeeva | B42: Living beings like humans and animals.
A43: Usage | B43: Mainly used for remedial purposes and in Prashna for identification of query.
A45: ODD / EVEN (MALE / FEMALE)
A46: Usage | B46: Used to find gender of siblings, children, etc.
A47: Odd (Male) | B47: Masculine, energetic, aggressive.
A48: Even (Female) | B48: Feminine, submissive, passive.
A50: BARREN & FRUITFUL SIGNS
A51: Usage | B51: Used to know about marriage and children. Jala Tatwa Rashis are fertile and fruitful.
A53: DAY / NIGHT
A54: Nocturnal | B54: Signs powerful during Night.
...

Sheet Sheet1
A4: House | B4: Name | C4: English Name | D4: Odd (Male)/ Even (Female) | E4: Chara/Sthira/Dwisabhava | F4: Abni/Vayu/Prithvi/Jala | G4: NEWS | H4: Varna | I4: Purusharthas | J4: Trigunas | K4: Constitution | L4: Barren & Fruitful signs | M4: Day / Night | N4: Rising Positions | O4: Legs | P4: Tridosha | Q4: Colours | R4: Places | S4: Jyothirlingas | T4: Kala Purusha Body Parts | U4: Mindset of the person
A5: 1 | B5: Mesha | C5: Aries | D5: Odd | E5: Chara | F5: Agni | G5: East | H5: Kshatriya | I5: Dharma | J5: Rajasika | K5: Dhatu | L5: Barren | M5: Nocturnal | N5: Prushtodaya | O5: Chatuspada | P5: Pitha | Q5: Red | R5: Forest | S5: Rameshwaram | T5: Head | U5: Energetic, Active, Change, Aggressive, Initiative, Impulsive, Restless, Bold, Wants to Lead
A6: 2 | B6: Vrishaba | C6: Taurus | D6: Even | E6: Sthira | F6: Prithvi | G6: South | H6: Vysya | I6: Artha | J6: Rajasika | K6: Moola | L6: Semi Fruitful | M6: Nocturnal | N6: Prushtodaya | O6: Chatuspada | P6: Vatha | Q6: White | R6: Agricultural land | S6: Somnatheshwara | T6: Face, Eye, Mouth | U6: Stability, Focused, Practical, Patience, Nourishment, Charming, Responsibility, Satisfied, Don’t like change, Stubborn
A7: 3 | B7: Mithuna | C7: Gemini | D7: Odd | E7: Dwisabhava | F7: Vayu | G7: West | H7: Shudra | I7: Kama | J7: Rajasika | K7: Jeeva | L7: Barren | M7: Nocturnal | N7: Shirsodaya | O7: Dwipada | P7: Tridosha | Q7: Green | R7: Bedroom | S7: Nageshwara | T7: Neck, Arms | U7: Good communication, Intelligent, Artistic, Confused, Humorous, Multitasking, Creative, Adaptable, Fickle minded, Writers, indicates the neck of the Kala purusha , neck enables the head to turn and see in different directions so that is the reason mithuna ppl are always searching for different options
A8: 4 | B8: Karkataka | C8: Cancer | D8: Even | E8: Chara | F8: Jala | G8: North | H8: Brahmin | I8: Moksha | J8: Sathvik | K8: Dhatu | L8: Fruitful | M8: Nocturnal | N8: Prushtodaya | O8: Jalachara | P8: Kapha | Q8: Pink | R8: River | S8: Omkareshwara | T8: Heart, Lungs | U8: Emotional, Sensitive, Honest, Mood swings, Motherly nature, Peace loving, Warmth, Nurturing, Soft nature, Psychic
A9: 5 | B9: Simha | C9: Leo | D9: Odd | E9: Sthira | F9: Agni | G9: East | H9: Kshatriya | I9: Dharma | J9: Sathvik | K9: Moola | L9: Barren | M9: Diurnal | N9: Shirsodaya | O9: Vanachara | P9: Pitha | Q9: Off white | R9: Mountain | S9: Vaidyanath | T9: Stomach, Womb | U9: Energetic, Aggressive, Egoistic, Good in administration, Generous, Dominating, Competitve, Leaders, Helping nature, Self respect.
A10: 6 | B10: Kanya | C10: Virgo | D10: Even | E10: Dwisabhava | F10: Prithvi | G10: South | H10: Vysya | I10: Artha | J10: Tamasika | K10: Jeeva | L10: Barren | M10: Diurnal | N10: Shirsodaya | O10: Dwipada | P10: Vatha | Q10: Variegeted | R10: Gardens | S10: Mallikarjuna | T10: Hip, Intestine | U10: Practical, Critical, Perfectionist, Cleanliness, Observant, Intelligent, Feminine Looks, Reserved, Calculated risk, Organised. Highly logical and analytical.
A11: 7 | B11: Tula | C11: Libra | D11: Odd | E11: Chara | F11: Vayu | G11: West | H11: Shudra | I11: Kama | J11: Rajasika | K11: Dhatu | L11: Semi Fruitful | M11: Diurnal | N11: Shirsodaya | O11: Dwipada | P11: Vatha | Q11: Black | R11: Business Place | S11: Mahakaleshwar | T11: Kidneys | U11: Attractive, Extroverts, Well Mannered, Peace makers, Diplomatic, Good negotiators, Charming, Foresight and planning, good advice givers, business minded
A12: 8 | B12: Vrischika | C12: Scorpio | D12: Even | E12: Sthira | F12: Jala | G12: North | H12: Brahmin | I12: Moksha | J12: Rajasika | K12: Moola | L12: Fruitful | M12: Diurnal | N12: Shirsodaya | O12: Keeta | P12: Kapha | Q12: Saffron | R12: Hole / Cavity | S12: Grishneshwar | T12: Private Parts | U12: Secretive, Pessimistic, Possessive, Good researchers, Revenge, Penetrating Gaze, Mood swings, Good imagination, Fears and Phobias, Anxiety
A13: 9 | B13: Dhanur | C13: Sagittarius | D13: Odd | E13: Dwisabhava | F13: Agni | G13: East | H13: Kshatriya | I13: Dharma | J13: Sathvik | K13: Jeeva | L13: Semi Fruitful | M13: Nocturnal | N13: Prushtodaya | O13: Dwipada 1st half / Chatuspada 2nd half | P13: Pitha | Q13: Golden | R13: Palace | S13: Kashi Vishwanath | T13: Thighs | U13: Fun Loving, Adventurous, Very Optimistic, Confident, Attractive, Traditional, Good nature, Idealistic, Active, Competitive
A14: 10 | B14: Makara | C14: Capricorn | D14: Even | E14: Chara | F14: Prithvi | G14: South | H14: Vysya | I14: Artha | J14: Tamasika | K14: Dhatu | L14: Semi Fruitful | M14: Nocturnal | N14: Prushtodaya | O14: Chatuspada 1st half / Jalachara 2nd half | P14: Vatha | Q14: Various colours | R14: Watery Forest / Marshlands | S14: Bhima Shankara | T14: Knees | U14: Hard Workers, Straight Forward talkers, Methodical, Systematical, Ambitious, Practical, Rational, Perfectionist, Calculative, Stress
A15: 11 | B15: Kumbha | C15: Aquarius | D15: Odd | E15: Sthira | F15: Vayu | G15: West | H15: Shudra | I15: Kama | J15: Tamasika | K15: Moola | L15: Semi Fruitful | M15: Diurnal | N15: Shirsodaya | O15: Dwipada | P15: Vatha | Q15: Dark Brown | R15: Potters Place | S15: Kedarnath | T15: Ankles, Legs | U15: Sharp and quick, Emotional detachment, Stubborn, Mature, Creative, Friendly, Scientific, Philosophical, Original thinking, Rebel
A16: 12 | B16: Meena | C16: Pisces | D16: Even | E16: Dwisabhava | F16: Jala | G16: North | H16: Brahmin | I16: Moksha | J16: Sathvik | K16: Jeeva | L16: Fruitful | M16: Diurnal | N16: Ubhadaya | O16: Jalachara | P16: Kapha | Q16: White | R16: Ocean | S16: Tryambakeshwar | T16: Feet | U16: Very Moody, Loyal, Loving, Hopeful, Spiritual, Influenced easily, big change, very emotional, beautiful, highly satvik

Sheet Explanations
B3: Abni/Vayu/Prithvi/Jala
B5: 1 ) Used for giving Pariharas like Homa or lighting of lamps for Agni tatwa rashis. Abhisheka , Teerthasthana for Jala Tatwa rashis
B6: Chanting of Mantras for Vayu tatwa rashis
B7: Charity for Prithwi tatwa rashis
B8: 2 ) To check for natural calamities like earthquake , tsunami , fire accidents in Mundane Astology
B10: AGNI ( Firy ) TATWA Guna :Energetic , hot , active , Strong will , Assertive , independent , likes popularity , sometimes dominating , likes to be in position
B11: Vayu ( Airy ) Tatwa Guna : Creative , Intellectual . Logical , good planners , balanced , nervous
B12: Prithvi ( Earthy )Tatwa Guna : Perseverence , stability , Hard work, Materialistic , Practical ,self centered, stubborn
B13: Jala ( Watery ) Tatwa Guna :Emotional , devotional , Compassionate , Receptive , intutive , psychic, suspicious
B15: Chara Rashis or Moveable Signs ( Mesha , Karkataka , Tula , Vrischika ) Flexible , adoptable , dynamic, achievers ,
B16: Sthira Rashis or Fixed Signs (Vrishabha , Simha , Vrischika , Kumbha ) Rigid , firm on their decisions, stubborn ,determined, permanent ,impractical
B17: Dwiswabhava Rashis or Dual Signs ( all corner signs ) flexible or rigid depending on situation , indecisiveness , too cautious ,calculative , worries about what others woild think
... B130: while Janma Rashi indicates the mentality of the person

Sheet Exhalted or Debilitated
B2: English Name | C2: Lord | D2: MTR | E2: Exhalted | F2: Debilitated
B3: Aries | C3: Mars | D3: Yes | E3: Sun | F3: Saturn
B4: Taurus | C4: Venus | D4: Yes | E4: Rahu, Moon | F4: Ketu
B5: Gemini | C5: Mercury
B6: Cancer | C6: Moon | E6: Jupiter | F6: Mars
B7: Leo | C7: Sun | D7: Yes
B8: Virgo | C8: Mercury | D8: Yes | E8: Mercury | F8: Venus
B9: Libra | C9: Venus | D9: Yes | E9: Saturn | F9: Sun
B10: Scorpio | C10: Mars | E10: Ketu | F10: Rahu, Moon
B11: Sagittarius | C11: Jupiter | D11: Yes
B12: Capricorn | C12: Saturn | E12: Mars | F12: Jupiter
B13: Aquarius | C13: Saturn | D13: Yes
B14: Pisces | C14: Jupiter | E14: Venus | F14: Mercury

Sheet Tithi
F2: TITHI CALCULATOR (Live)
B3: Tithi number | C3: Tithi name | D3: Sun–Moon angular distance | F3: Concept | G3: A tithi is formed every 12° of angular separation between Moon and Sun (Moon ahead of Sun). 30 tithis per lunar month — 15 Shukla (waxing, 0°–180°) + 15 Krishna (waning, 180°–360°). Amavasya = Moon within 12° behind Sun. Pournima = Moon 168°–180° ahead of Sun.
B4: 1 | C4: Pratipada | D4: 0° to 12°
B5: 2 | C5: Dwitiya | D5: 12° to 24° | F5: Sun longitude (° in zodiac) | G5: =IF(OR(Input!C13="",Input!E13=""),"",(Input!C13-1)*30+Input!E13) -> 11.48
B6: 3 | C6: Tritiya | D6: 24° to 36° | F6: Moon longitude (° in zodiac) | G6: =IF(OR(Input!C14="",Input!E14=""),"",(Input!C14-1)*30+Input!E14) -> 346.56
B7: 4 | C7: Chaturthi | D7: 36° to 48° | F7: Moon − Sun separation (0°–360°) | G7: =IF(OR(G5="",G6=""),"",MOD(G6-G5,360)) -> 335.08
B8: 5 | C8: Panchami | D8: 48° to 60° | F8: Tithi Number (1–30) | G8: =IF(G7="","",INT(G7/12)+1) -> 28
B9: 6 | C9: Shashthi | D9: 60° to 72° | F9: Tithi Name | G9: {=IF(G8="","",INDEX(C$4:C$33,G8))} -> Trayodashi
B10: 7 | C10: Saptami | D10: 72° to 84° | F10: Paksha | G10: =IF(G8="","",IF(G8<=15,"Shukla Paksha (Waxing) — Strong, Benefic","Krishna Paksha (Waning) — Weak, Malefic")) -> Krishna Paksha (Waning) — Weak, Malefic
B11: 8 | C11: Ashtami | D11: 84° to 96° | F11: Moon Strength Window | G11: =IF(G8="","",IF(G8<=15,"Strong (entire Shukla Paksha)",IF(G8<=22,"Moderate (Krishna Pratipada–Saptami)","Weak (Ashtami→Amavasya in Krishna Paksha)"))) -> Weak (Ashtami→Amavasya in Krishna Paksha)
B12: 9 | C12: Navami | D12: 96° to 108°
B13: 10 | C13: Dashami | D13: 108° to 120°
B14: 11 | C14: Ekadashi | D14: 120° to 132°
B15: 12 | C15: Dwadashi | D15: 132° to 144°
B16: 13 | C16: Trayodashi | D16: 144° to 156°
B17: 14 | C17: Chaturdashi | D17: 156° to 168°
B18: 15 | C18: Purnima / Amavasya | D18: 168° to 180°
B19: 16 | C19: Pratipada | D19: 180° to 192°
B20: 17 | C20: Dwitiya | D20: 192° to 204°
B21: 18 | C21: Tritiya | D21: 204° to 216°
B22: 19 | C22: Chaturthi | D22: 216° to 228°
B23: 20 | C23: Panchami | D23: 228° to 240°
... B33: 30 | C33: Purnima / Amavasya | D33: 348° to 360°
C36: A tithi is the lunar day in the Hindu calendar, defined by the angular separation between the Sun and the Moon; each tithi spans 12 degrees of that separation, and there are 30 tithis in a lunar month, split into Shukla Paksha and Krishna Paksha. For Thursday, 21 May 2026, the tithi is Shukla Paksha Panchami. Tithi meaning The 30 tithis are grouped as 15 waxing tithis and 15 waning tithis, with names such as Pratipada, Dwitiya, Tritiya, Chaturthi, Panchami, and so on up to Purnima or Amavasya depending on the phase. A tithi can begin or end at any time of day because it follows the Moon’s movement rather than the civil clock, so the tithi at sunrise is usually used for the day’s Panchang reading. Sun and Moon distance If you mean the physical distance, the average distance from Earth to the Sun is about 149.6 million kilometers (1 AU), and the average distance from Earth to the Moon is about 384,400 kilometers. The Sun is therefore roughly 400 times farther from Earth than the Moon. How tithi is determined A tithi is not measured in kilometers but in angular distance. When the Moon is 12 degrees ahead of the Sun, the first tithi begins; each additional 12 degrees advances the tithi by one step. For example, when the Moon is 12 to 24 degrees from the Sun, it is Dwitiya; when it is 48 to 60 degrees away, it is Panchami.
